Workbook

Sheet Summing.bothpivots
B1: pan | C1: vac | D1: sum | E1: pan | F1: vac | G1: sum | H1: pan | I1: vac | J1: sum | K1: pan | L1: vac | M1: sum | N1: pan | O1: vac | P1: sum | Q1: pan | R1: vac | S1: sum | T1: pan | U1: vac | V1: sum | W1: pan | X1: vac | Y1: sum | Z1: pan | AA1: vac | AB1: sum | AC1: pan | AD1: vac | AE1: sum | AF1: pan | AG1: vac | AH1: sum | AI1: pan | AJ1: vac | AK1: sum | AL1: pan | AM1: vac | AN1: sum | AO1: pan | AP1: vac | AQ1: sum | AR1: pan | AS1: vac | AT1: sum | AU1: pan | AV1: vac | AW1: sum | AX1: pan | AY1: vac | AZ1: sum | BA1: pan | BB1: vac | BC1: sum | BD1: pan | BE1: vac | BF1: sum | BG1: pan | BH1: vac | BI1: sum | BJ1: pan | BK1: vac | BL1: sum | BM1: pan | BN1: vac | BO1: sum | BP1: pan | BQ1: vac | BR1: sum | BS1: pan | BT1: vac | BU1: sum | BV1: pan | BW1: vac | BX1: sum | BY1: pan | BZ1: vac | CA1: sum | CB1: pan | CC1: vac | CD1: sum | CE1: pan | CF1: vac | CG1: sum | CH1: pan | CI1: vac | CJ1: sum | CK1: pan | CL1: vac | CM1: sum | CN1: pan | CO1: vac | CP1: sum | CQ1: pan | CR1: vac | CS1: sum
A2: Row Labels | D2: BU1 | G2: BU4 | J2: BU6 | M2: BU8 | P2: CE1 | S2: CE4 | V2: CE6 | Y2: CE8 | AB2: DS1 | AE2: DS4 | AH2: DS6 | AK2: DS8 | AN2: FA1 | AQ2: FA4 | AT2: FA6 | AW2: FA8 | AZ2: GL1 | BC2: GL4 | BF2: GL6 | BI2: GL8 | BL2: HO1 | BO2: HO4 | BR2: HO6 | BU2: HO8 | BX2: SV1 | CA2: SV4 | CD2: SV6 | CG2: SV8 | CJ2: TR1 | CM2: TR4 | CP2: TR6 | CS2: TR8
A3: Agapostemon.sericeus | B3: =_xlfn.XLOOKUP(A3,PanPivot!A:A,PanPivot!B:B) -> 0 | C3: =_xlfn.XLOOKUP(A3,VacPivot!A:A,VacPivot!B:B) -> 0 | D3: {=SUM(IFERROR(B3:C3,0))} -> 0 | E3: =_xlfn.XLOOKUP(A3,PanPivot!A:A,PanPivot!C:C) -> 0 | F3: =_xlfn.XLOOKUP(A3,VacPivot!A:A,VacPivot!D:D) -> 0 | G3: {=SUM(IFERROR(E3:F3,0))} -> 0 | H3: =_xlfn.XLOOKUP(A3,PanPivot!A:A,PanPivot!D:D) -> 0 | I3: =_xlfn.XLOOKUP(A3,VacPivot!A:A,VacPivot!E:E) -> 0 | J3: {=SUM(IFERROR(H3:I3,0))} -> 0 | K3: =_xlfn.XLOOKUP(A3,PanPivot!A:A,PanPivot!E:E) -> 0 | L3: =_xlfn.XLOOKUP(Summing.bothpivots!A3,VacPivot!A:A,VacPivot!F:F) -> 0 | M3: {=SUM(IFERROR(K3:L3,0))} -> 0 | N3: =_xlfn.XLOOKUP(A3,PanPivot!A:A,PanPivot!F:F) -> 1 | O3: =_xlfn.XLOOKUP(A3,VacPivot!A:A,VacPivot!AO:AO) -> 0 | P3: {=SUM(IFERROR(N3:O3,0))} -> 1 | Q3: =_xlfn.XLOOKUP(A3,PanPivot!A:A,PanPivot!G:G) -> 0 | R3: =_xlfn.XLOOKUP(A3,VacPivot!A:A,VacPivot!H:H) -> 0 | S3: {=SUM(IFERROR(Q3:R3,0))} -> 0 | T3: =_xlfn.XLOOKUP(A3,PanPivot!A:A,PanPivot!H:H) -> 0 | U3: =_xlfn.XLOOKUP(A3,VacPivot!A:A,VacPivot!I:I) -> 1 | V3: {=SUM(IFERROR(T3:U3,0))} -> 1 | W3: =_xlfn.XLOOKUP(A3,PanPivot!A:A,PanPivot!I:I) -> 0 | X3: =_xlfn.XLOOKUP(A3,VacPivot!A:A,VacPivot!J:J) -> 0 | Y3: {=SUM(IFERROR(W3:X3,0))} -> 0 | Z3: =_xlfn.XLOOKUP(A3,PanPivot!A:A,PanPivot!J:J) -> 0 | AA3: =_xlfn.XLOOKUP(A3,VacPivot!A:A,VacPivot!K:K) -> 0 | AB3: {=SUM(IFERROR(Z3:AA3,0))} -> 0 | AC3: =_xlfn.XLOOKUP(A3,PanPivot!A:A,PanPivot!K:K) -> 0 | AD3: =_xlfn.XLOOKUP(A3,VacPivot!A:A,VacPivot!M:M) -> 0 | AE3: {=SUM(IFERROR(AC3:AD3,0))} -> 0 | AF3: =_xlfn.XLOOKUP(A3,PanPivot!A:A,PanPivot!L:L) -> 0 | AG3: =_xlfn.XLOOKUP(A3,VacPivot!A:A,VacPivot!N:N) -> 0 | AH3: {=SUM(IFERROR(AF3:AG3,0))} -> 0 | AI3: =_xlfn.XLOOKUP(A3,PanPivot!A:A,PanPivot!M:M) -> 0 | AJ3: =_xlfn.XLOOKUP(A3,VacPivot!A:A,VacPivot!O:O) -> 0 | AK3: {=SUM(IFERROR(AI3:AJ3,0))} -> 0 | AL3: =_xlfn.XLOOKUP(A3,PanPivot!A:A,PanPivot!N:N) -> 0 | AM3: =_xlfn.XLOOKUP(A3,VacPivot!A:A,VacPivot!P:P) -> 0 | AN3: {=SUM(IFERROR(AL3:AM3,0))} -> 0 | AO3: =_xlfn.XLOOKUP(A3,PanPivot!A:A,PanPivot!O:O) -> 0 | AP3: =_xlfn.XLOOKUP(A3,VacPivot!A:A,VacPivot!R:R) -> 0 | AQ3: {=SUM(IFERROR(AO3:AP3,0))} -> 0 | AR3: =_xlfn.XLOOKUP(A3,PanPivot!A:A,PanPivot!P:P) -> 0 | AS3: =_xlfn.XLOOKUP(A3,VacPivot!A:A,VacPivot!S:S) -> 2 | AT3: {=SUM(IFERROR(AR3:AS3,0))} -> 2 | AU3: =_xlfn.XLOOKUP(A3,PanPivot!A:A,PanPivot!Q:Q) -> 0 | AV3: =_xlfn.XLOOKUP(A3,VacPivot!A:A,VacPivot!T:T) -> 2 | AW3: {=SUM(IFERROR(AU3:AV3,0))} -> 2 | AX3: =_xlfn.XLOOKUP(A3,PanPivot!A:A,PanPivot!R:R) -> 0 | AY3: =_xlfn.XLOOKUP(A3,VacPivot!A:A,VacPivot!U:U) -> 0 | AZ3: {=SUM(IFERROR(AX3:AY3,0))} -> 0 | BA3: =_xlfn.XLOOKUP(A3,PanPivot!A:A,PanPivot!S:S) -> 2 | BB3: =_xlfn.XLOOKUP(A3,VacPivot!A:A,VacPivot!W:W) -> 3 | BC3: {=SUM(IFERROR(BA3:BB3,0))} -> 5 | BD3: =_xlfn.XLOOKUP(A3,PanPivot!A:A,PanPivot!T:T) -> 1 | BE3: =_xlfn.XLOOKUP(A3,VacPivot!A:A,VacPivot!X:X) -> 0 | BF3: {=SUM(IFERROR(BD3:BE3,0))} -> 1 | BG3: =_xlfn.XLOOKUP(A3,PanPivot!A:A,PanPivot!U:U) -> 0 | BH3: =_xlfn.XLOOKUP(Summing.bothpivots!A3,VacPivot!A:A,VacPivot!Y:Y) -> 0 | BI3: {=SUM(IFERROR(BG3:BH3,0))} -> 0 | BJ3: =_xlfn.XLOOKUP(A3,PanPivot!A:A,PanPivot!V:V) -> 0 | BK3: =_xlfn.XLOOKUP(A3,VacPivot!A:A,VacPivot!Z:Z) -> 0 | BL3: {=SUM(IFERROR(BJ3:BK3,0))} -> 0 | BM3: =_xlfn.XLOOKUP(A3,PanPivot!A:A,PanPivot!W:W) -> 2 | BN3: =_xlfn.XLOOKUP(A3,VacPivot!A:A,VacPivot!AB:AB) -> 0 | BO3: {=SUM(IFERROR(BM3:BN3,0))} -> 2 | BP3: =_xlfn.XLOOKUP(A3,PanPivot!A:A,PanPivot!X:X) -> 0 | BQ3: =_xlfn.XLOOKUP(A3,VacPivot!A:A,VacPivot!AC:AC) -> 0 | BR3: {=SUM(IFERROR(BP3:BQ3,0))} -> 0 | BS3: =_xlfn.XLOOKUP(Summing.bothpivots!A3,PanPivot!A:A,PanPivot!Y:Y) -> 0 | BT3: =_xlfn.XLOOKUP(A3,VacPivot!A:A,VacPivot!AD:AD) -> 0 | BU3: {=SUM(IFERROR(BS3:BT3,0))} -> 0 | BV3: =_xlfn.XLOOKUP(A3,PanPivot!A:A,PanPivot!Z:Z) -> 0 | BW3: =_xlfn.XLOOKUP(A3,VacPivot!A:A,VacPivot!AE:AE) -> 1 | BX3: {=SUM(IFERROR(BV3:BW3,0))} -> 1 | BY3: =_xlfn.XLOOKUP(A3,PanPivot!A:A,PanPivot!AA:AA) -> 0 | BZ3: =_xlfn.XLOOKUP(A3,VacPivot!A:A,VacPivot!AG:AG) -> 0 | CA3: {=SUM(IFERROR(BY3:BZ3,0))} -> 0 | CB3: =_xlfn.XLOOKUP(A3,PanPivot!A:A,PanPivot!AB:AB) -> 0 | CC3: =_xlfn.XLOOKUP(A3,VacPivot!A:A,VacPivot!AH:AH) -> 0 | CD3: {=SUM(IFERROR(CB3:CC3,0))} -> 0 | CE3: =_xlfn.XLOOKUP(A3,PanPivot!A:A,PanPivot!AC:AC) -> 0 | CF3: =_xlfn.XLOOKUP(A3,VacPivot!A:A,VacPivot!AI:AI) -> 0 | CG3: {=SUM(IFERROR(CE3:CF3,0))} -> 0 | CH3: =_xlfn.XLOOKUP(A3,PanPivot!A:A,PanPivot!AD:AD) -> 0 | CI3: =_xlfn.XLOOKUP(A3,VacPivot!A:A,VacPivot!AJ:AJ) -> 0 | CJ3: {=SUM(IFERROR(CH3:CI3,0))} -> 0 | CK3: =_xlfn.XLOOKUP(A3,PanPivot!A:A,PanPivot!AE:AE) -> 0 | CL3: =_xlfn.XLOOKUP(A3,VacPivot!A:A,VacPivot!AL:AL) -> 0 | CM3: {=SUM(IFERROR(CK3:CL3,0))} -> 0 | CN3: =_xlfn.XLOOKUP(A3,PanPivot!A:A,PanPivot!AF:AF) -> 0 | CO3: =_xlfn.XLOOKUP(A3,VacPivot!A:A,VacPivot!AM:AM) -> 0 | CP3: {=SUM(IFERROR(CN3:CO3,0))} -> 0 | CQ3: =_xlfn.XLOOKUP(A3,PanPivot!A:A,PanPivot!AG:AG) -> 0 | CR3: =_xlfn.XLOOKUP(A3,VacPivot!A:A,VacPivot!AN:AN) -> 0 | CS3: {=SUM(IFERROR(CQ3:CR3,0))} -> 0
A4: Agapostemon.texanus | B4: =_xlfn.XLOOKUP(A4,PanPivot!A:A,PanPivot!B:B) -> 0 | C4: =_xlfn.XLOOKUP(A4,VacPivot!A:A,VacPivot!B:B) -> 0 | D4: {=SUM(IFERROR(B4:C4,0))} -> 0 | E4: =_xlfn.XLOOKUP(A4,PanPivot!A:A,PanPivot!C:C) -> 0 | F4: =_xlfn.XLOOKUP(A4,VacPivot!A:A,VacPivot!D:D) -> 0 | G4: {=SUM(IFERROR(E4:F4,0))} -> 0 | H4: =_xlfn.XLOOKUP(A4,PanPivot!A:A,PanPivot!D:D) -> 0 | I4: =_xlfn.XLOOKUP(A4,VacPivot!A:A,VacPivot!E:E) -> 0 | J4: {=SUM(IFERROR(H4:I4,0))} -> 0 | K4: =_xlfn.XLOOKUP(A4,PanPivot!A:A,PanPivot!E:E) -> 0 | L4: =_xlfn.XLOOKUP(Summing.bothpivots!A4,VacPivot!A:A,VacPivot!F:F) -> 0 | M4: {=SUM(IFERROR(K4:L4,0))} -> 0 | N4: =_xlfn.XLOOKUP(A4,PanPivot!A:A,PanPivot!F:F) -> 0 | O4: =_xlfn.XLOOKUP(A4,VacPivot!A:A,VacPivot!AO:AO) -> 0 | P4: {=SUM(IFERROR(N4:O4,0))} -> 0 | Q4: =_xlfn.XLOOKUP(A4,PanPivot!A:A,PanPivot!G:G) -> 6 | R4: =_xlfn.XLOOKUP(A4,VacPivot!A:A,VacPivot!H:H) -> 0 | S4: {=SUM(IFERROR(Q4:R4,0))} -> 6 | T4: =_xlfn.XLOOKUP(A4,PanPivot!A:A,PanPivot!H:H) -> 2 | U4: =_xlfn.XLOOKUP(A4,VacPivot!A:A,VacPivot!I:I) -> 4 | V4: {=SUM(IFERROR(T4:U4,0))} -> 6 | W4: =_xlfn.XLOOKUP(A4,PanPivot!A:A,PanPivot!I:I) -> 0 | X4: =_xlfn.XLOOKUP(A4,VacPivot!A:A,VacPivot!J:J) -> 1 | Y4: {=SUM(IFERROR(W4:X4,0))} -> 1 | Z4: =_xlfn.XLOOKUP(A4,PanPivot!A:A,PanPivot!J:J) -> 0 | AA4: =_xlfn.XLOOKUP(A4,VacPivot!A:A,VacPivot!K:K) -> 0 | AB4: {=SUM(IFERROR(Z4:AA4,0))} -> 0 | AC4: =_xlfn.XLOOKUP(A4,PanPivot!A:A,PanPivot!K:K) -> 0 | AD4: =_xlfn.XLOOKUP(A4,VacPivot!A:A,VacPivot!M:M) -> 0 | AE4: {=SUM(IFERROR(AC4:AD4,0))} -> 0 | AF4: =_xlfn.XLOOKUP(A4,PanPivot!A:A,PanPivot!L:L) -> 0 | AG4: =_xlfn.XLOOKUP(A4,VacPivot!A:A,VacPivot!N:N) -> 0 | AH4: {=SUM(IFERROR(AF4:AG4,0))} -> 0 | AI4: =_xlfn.XLOOKUP(A4,PanPivot!A:A,PanPivot!M:M) -> 0 | AJ4: =_xlfn.XLOOKUP(A4,VacPivot!A:A,VacPivot!O:O) -> 0 | AK4: {=SUM(IFERROR(AI4:AJ4,0))} -> 0 | AL4: =_xlfn.XLOOKUP(A4,PanPivot!A:A,PanPivot!N:N) -> 0 | AM4: =_xlfn.XLOOKUP(A4,VacPivot!A:A,VacPivot!P:P) -> 0 | AN4: {=SUM(IFERROR(AL4:AM4,0))} -> 0 | AO4: =_xlfn.XLOOKUP(A4,PanPivot!A:A,PanPivot!O:O) -> 1 | AP4: =_xlfn.XLOOKUP(A4,VacPivot!A:A,VacPivot!R:R) -> 0 | AQ4: {=SUM(IFERROR(AO4:AP4,0))} -> 1 | AR4: =_xlfn.XLOOKUP(A4,PanPivot!A:A,PanPivot!P:P) -> 0 | AS4: =_xlfn.XLOOKUP(A4,VacPivot!A:A,VacPivot!S:S) -> 1 | AT4: {=SUM(IFERROR(AR4:AS4,0))} -> 1 | AU4: =_xlfn.XLOOKUP(A4,PanPivot!A:A,PanPivot!Q:Q) -> 0 | AV4: =_xlfn.XLOOKUP(A4,VacPivot!A:A,VacPivot!T:T) -> 1 | AW4: {=SUM(IFERROR(AU4:AV4,0))} -> 1 | AX4: =_xlfn.XLOOKUP(A4,PanPivot!A:A,PanPivot!R:R) -> 0 | AY4: =_xlfn.XLOOKUP(A4,VacPivot!A:A,VacPivot!U:U) -> 0 | AZ4: {=SUM(IFERROR(AX4:AY4,0))} -> 0 | BA4: =_xlfn.XLOOKUP(A4,PanPivot!A:A,PanPivot!S:S) -> 0 | BB4: =_xlfn.XLOOKUP(A4,VacPivot!A:A,VacPivot!W:W) -> 1 | BC4: {=SUM(IFERROR(BA4:BB4,0))} -> 1 | BD4: =_xlfn.XLOOKUP(A4,PanPivot!A:A,PanPivot!T:T) -> 0 | BE4: =_xlfn.XLOOKUP(A4,VacPivot!A:A,VacPivot!X:X) -> 1 | BF4: {=SUM(IFERROR(BD4:BE4,0))} -> 1 | BG4: =_xlfn.XLOOKUP(A4,PanPivot!A:A,PanPivot!U:U) -> 1 | BH4: =_xlfn.XLOOKUP(Summing.bothpivots!A4,VacPivot!A:A,VacPivot!Y:Y) -> 1 | BI4: {=SUM(IFERROR(BG4:BH4,0))} -> 2 | BJ4: =_xlfn.XLOOKUP(A4,PanPivot!A:A,PanPivot!V:V) -> 0 | BK4: =_xlfn.XLOOKUP(A4,VacPivot!A:A,VacPivot!Z:Z) -> 1 | BL4: {=SUM(IFERROR(BJ4:BK4,0))} -> 1 | BM4: =_xlfn.XLOOKUP(A4,PanPivot!A:A,PanPivot!W:W) -> 0 | BN4: =_xlfn.XLOOKUP(A4,VacPivot!A:A,VacPivot!AB:AB) -> 0 | BO4: {=SUM(IFERROR(BM4:BN4,0))} -> 0 | BP4: =_xlfn.XLOOKUP(A4,PanPivot!A:A,PanPivot!X:X) -> 2 | BQ4: =_xlfn.XLOOKUP(A4,VacPivot!A:A,VacPivot!AC:AC) -> 0 | BR4: {=SUM(IFERROR(BP4:BQ4,0))} -> 2 | BS4: =_xlfn.XLOOKUP(Summing.bothpivots!A4,PanPivot!A:A,PanPivot!Y:Y) -> 0 | BT4: =_xlfn.XLOOKUP(A4,VacPivot!A:A,VacPivot!AD:AD) -> 1 | BU4: {=SUM(IFERROR(BS4:BT4,0))} -> 1 | BV4: =_xlfn.XLOOKUP(A4,PanPivot!A:A,PanPivot!Z:Z) -> 0 | BW4: =_xlfn.XLOOKUP(A4,VacPivot!A:A,VacPivot!AE:AE) -> 0 | BX4: {=SUM(IFERROR(BV4:BW4,0))} -> 0 | BY4: =_xlfn.XLOOKUP(A4,PanPivot!A:A,PanPivot!AA:AA) -> 0 | BZ4: =_xlfn.XLOOKUP(A4,VacPivot!A:A,VacPivot!AG:AG) -> 0 | CA4: {=SUM(IFERROR(BY4:BZ4,0))} -> 0 | CB4: =_xlfn.XLOOKUP(A4,PanPivot!A:A,PanPivot!AB:AB) -> 0 | CC4: =_xlfn.XLOOKUP(A4,VacPivot!A:A,VacPivot!AH:AH) -> 0 | CD4: {=SUM(IFERROR(CB4:CC4,0))} -> 0 | CE4: =_xlfn.XLOOKUP(A4,PanPivot!A:A,PanPivot!AC:AC) -> 0 | CF4: =_xlfn.XLOOKUP(A4,VacPivot!A:A,VacPivot!AI:AI) -> 1 | CG4: {=SUM(IFERROR(CE4:CF4,0))} -> 1 | CH4: =_xlfn.XLOOKUP(A4,PanPivot!A:A,PanPivot!AD:AD) -> 0 | CI4: =_xlfn.XLOOKUP(A4,VacPivot!A:A,VacPivot!AJ:AJ) -> 2 | CJ4: {=SUM(IFERROR(CH4:CI4,0))} -> 2 | CK4: =_xlfn.XLOOKUP(A4,PanPivot!A:A,PanPivot!AE:AE) -> 0 | CL4: =_xlfn.XLOOKUP(A4,VacPivot!A:A,VacPivot!AL:AL) -> 0 | CM4: {=SUM(IFERROR(CK4:CL4,0))} -> 0 | CN4: =_xlfn.XLOOKUP(A4,PanPivot!A:A,PanPivot!AF:AF) -> 0 | CO4: =_xlfn.XLOOKUP(A4,VacPivot!A:A,VacPivot!AM:AM) -> 1 | CP4: {=SUM(IFERROR(CN4:CO4,0))} -> 1 | CQ4: =_xlfn.XLOOKUP(A4,PanPivot!A:A,PanPivot!AG:AG) -> 0 | CR4: =_xlfn.XLOOKUP(A4,VacPivot!A:A,VacPivot!AN:AN) -> 0 | CS4: {=SUM(IFERROR(CQ4:CR4,0))} -> 0
A5: Agapostemon.virescens | B5: =_xlfn.XLOOKUP(A5,PanPivot!A:A,PanPivot!B:B) -> 0 | C5: =_xlfn.XLOOKUP(A5,VacPivot!A:A,VacPivot!B:B) -> 1 | D5: {=SUM(IFERROR(B5:C5,0))} -> 1 | E5: =_xlfn.XLOOKUP(A5,PanPivot!A:A,PanPivot!C:C) -> 0 | F5: =_xlfn.XLOOKUP(A5,VacPivot!A:A,VacPivot!D:D) -> 0 | G5: {=SUM(IFERROR(E5:F5,0))} -> 0 | H5: =_xlfn.XLOOKUP(A5,PanPivot!A:A,PanPivot!D:D) -> 0 | I5: =_xlfn.XLOOKUP(A5,VacPivot!A:A,VacPivot!E:E) -> 2 | J5: {=SUM(IFERROR(H5:I5,0))} -> 2 | K5: =_xlfn.XLOOKUP(A5,PanPivot!A:A,PanPivot!E:E) -> 0 | L5: =_xlfn.XLOOKUP(Summing.bothpivots!A5,VacPivot!A:A,VacPivot!F:F) -> 4 | M5: {=SUM(IFERROR(K5:L5,0))} -> 4 | N5: =_xlfn.XLOOKUP(A5,PanPivot!A:A,PanPivot!F:F) -> 3 | O5: =_xlfn.XLOOKUP(A5,VacPivot!A:A,VacPivot!AO:AO) -> 0 | P5: {=SUM(IFERROR(N5:O5,0))} -> 3 | Q5: =_xlfn.XLOOKUP(A5,PanPivot!A:A,PanPivot!G:G) -> 1 | R5: =_xlfn.XLOOKUP(A5,VacPivot!A:A,VacPivot!H:H) -> 16 | S5: {=SUM(IFERROR(Q5:R5,0))} -> 17 | T5: =_xlfn.XLOOKUP(A5,PanPivot!A:A,PanPivot!H:H) -> 2 | U5: =_xlfn.XLOOKUP(A5,VacPivot!A:A,VacPivot!I:I) -> 5 | V5: {=SUM(IFERROR(T5:U5,0))} -> 7 | W5: =_xlfn.XLOOKUP(A5,PanPivot!A:A,PanPivot!I:I) -> 0 | X5: =_xlfn.XLOOKUP(A5,VacPivot!A:A,VacPivot!J:J) -> 2 | Y5: {=SUM(IFERROR(W5:X5,0))} -> 2 | Z5: =_xlfn.XLOOKUP(A5,PanPivot!A:A,PanPivot!J:J) -> 0 | AA5: =_xlfn.XLOOKUP(A5,VacPivot!A:A,VacPivot!K:K) -> 0 | AB5: {=SUM(IFERROR(Z5:AA5,0))} -> 0 | AC5: =_xlfn.XLOOKUP(A5,PanPivot!A:A,PanPivot!K:K) -> 1 | AD5: =_xlfn.XLOOKUP(A5,VacPivot!A:A,VacPivot!M:M) -> 10 | AE5: {=SUM(IFERROR(AC5:AD5,0))} -> 11 | AF5: =_xlfn.XLOOKUP(A5,PanPivot!A:A,PanPivot!L:L) -> 0 | AG5: =_xlfn.XLOOKUP(A5,VacPivot!A:A,VacPivot!N:N) -> 0 | AH5: {=SUM(IFERROR(AF5:AG5,0))} -> 0 | AI5: =_xlfn.XLOOKUP(A5,PanPivot!A:A,PanPivot!M:M) -> 0 | AJ5: =_xlfn.XLOOKUP(A5,VacPivot!A:A,VacPivot!O:O) -> 1 | AK5: {=SUM(IFERROR(AI5:AJ5,0))} -> 1 | AL5: =_xlfn.XLOOKUP(A5,PanPivot!A:A,PanPivot!N:N) -> 0 | AM5: =_xlfn.XLOOKUP(A5,VacPivot!A:A,VacPivot!P:P) -> 1 | AN5: {=SUM(IFERROR(AL5:AM5,0))} -> 1 | AO5: =_xlfn.XLOOKUP(A5,PanPivot!A:A,PanPivot!O:O) -> 0 | AP5: =_xlfn.XLOOKUP(A5,VacPivot!A:A,VacPivot!R:R) -> 1 | AQ5: {=SUM(IFERROR(AO5:AP5,0))} -> 1 | AR5: =_xlfn.XLOOKUP(A5,PanPivot!A:A,PanPivot!P:P) -> 0 | AS5: =_xlfn.XLOOKUP(A5,VacPivot!A:A,VacPivot!S:S) -> 1 | AT5: {=SUM(IFERROR(AR5:AS5,0))} -> 1 | AU5: =_xlfn.XLOOKUP(A5,PanPivot!A:A,PanPivot!Q:Q) -> 0 | AV5: =_xlfn.XLOOKUP(A5,VacPivot!A:A,VacPivot!T:T) -> 2 | AW5: {=SUM(IFERROR(AU5:AV5,0))} -> 2 | AX5: =_xlfn.XLOOKUP(A5,PanPivot!A:A,PanPivot!R:R) -> 0 | AY5: =_xlfn.XLOOKUP(A5,VacPivot!A:A,VacPivot!U:U) -> 1 | AZ5: {=SUM(IFERROR(AX5:AY5,0))} -> 1 | BA5: =_xlfn.XLOOKUP(A5,PanPivot!A:A,PanPivot!S:S) -> 3 | BB5: =_xlfn.XLOOKUP(A5,VacPivot!A:A,VacPivot!W:W) -> 0 | BC5: {=SUM(IFERROR(BA5:BB5,0))} -> 3 | BD5: =_xlfn.XLOOKUP(A5,PanPivot!A:A,PanPivot!T:T) -> 0 | BE5: =_xlfn.XLOOKUP(A5,VacPivot!A:A,VacPivot!X:X) -> 0 | BF5: {=SUM(IFERROR(BD5:BE5,0))} -> 0 | BG5: =_xlfn.XLOOKUP(A5,PanPivot!A:A,PanPivot!U:U) -> 0 | BH5: =_xlfn.XLOOKUP(Summing.bothpivots!A5,VacPivot!A:A,VacPivot!Y:Y) -> 1 | BI5: {=SUM(IFERROR(BG5:BH5,0))} -> 1 | BJ5: =_xlfn.XLOOKUP(A5,PanPivot!A:A,PanPivot!V:V) -> 0 | BK5: =_xlfn.XLOOKUP(A5,VacPivot!A:A,VacPivot!Z:Z) -> 5 | BL5: {=SUM(IFERROR(BJ5:BK5,0))} -> 5 | BM5: =_xlfn.XLOOKUP(A5,PanPivot!A:A,PanPivot!W:W) -> 0 | BN5: =_xlfn.XLOOKUP(A5,VacPivot!A:A,VacPivot!AB:AB) -> 6 | BO5: {=SUM(IFERROR(BM5:BN5,0))} -> 6 | BP5: =_xlfn.XLOOKUP(A5,PanPivot!A:A,PanPivot!X:X) -> 1 | BQ5: =_xlfn.XLOOKUP(A5,VacPivot!A:A,VacPivot!AC:AC) -> 1 | BR5: {=SUM(IFERROR(BP5:BQ5,0))} -> 2 | BS5: =_xlfn.XLOOKUP(Summing.bothpivots!A5,PanPivot!A:A,PanPivot!Y:Y) -> 0 | BT5: =_xlfn.XLOOKUP(A5,VacPivot!A:A,VacPivot!AD:AD) -> 1 | BU5: {=SUM(IFERROR(BS5:BT5,0))} -> 1 | BV5: =_xlfn.XLOOKUP(A5,PanPivot!A:A,PanPivot!Z:Z) -> 0 | BW5: =_xlfn.XLOOKUP(A5,VacPivot!A:A,VacPivot!AE:AE) -> 6 | BX5: {=SUM(IFERROR(BV5:BW5,0))} -> 6 | BY5: =_xlfn.XLOOKUP(A5,PanPivot!A:A,PanPivot!AA:AA) -> 1 | BZ5: =_xlfn.XLOOKUP(A5,VacPivot!A:A,VacPivot!AG:AG) -> 0 | CA5: {=SUM(IFERROR(BY5:BZ5,0))} -> 1 | CB5: =_xlfn.XLOOKUP(A5,PanPivot!A:A,PanPivot!AB:AB) -> 0 | CC5: =_xlfn.XLOOKUP(A5,VacPivot!A:A,VacPivot!AH:AH) -> 0 | CD5: {=SUM(IFERROR(CB5:CC5,0))} -> 0 | CE5: =_xlfn.XLOOKUP(A5,PanPivot!A:A,PanPivot!AC:AC) -> 0 | CF5: =_xlfn.XLOOKUP(A5,VacPivot!A:A,VacPivot!AI:AI) -> 1 | CG5: {=SUM(IFERROR(CE5:CF5,0))} -> 1 | CH5: =_xlfn.XLOOKUP(A5,PanPivot!A:A,PanPivot!AD:AD) -> 2 | CI5: =_xlfn.XLOOKUP(A5,VacPivot!A:A,VacPivot!AJ:AJ) -> 10 | CJ5: {=SUM(IFERROR(CH5:CI5,0))} -> 12 | CK5: =_xlfn.XLOOKUP(A5,PanPivot!A:A,PanPivot!AE:AE) -> 0 | CL5: =_xlfn.XLOOKUP(A5,VacPivot!A:A,VacPivot!AL:AL) -> 0 | CM5: {=SUM(IFERROR(CK5:CL5,0))} -> 0 | CN5: =_xlfn.XLOOKUP(A5,PanPivot!A:A,PanPivot!AF:AF) -> 1 | CO5: =_xlfn.XLOOKUP(A5,VacPivot!A:A,VacPivot!AM:AM) -> 0 | CP5: {=SUM(IFERROR(CN5:CO5,0))} -> 1 | CQ5: =_xlfn.XLOOKUP(A5,PanPivot!A:A,PanPivot!AG:AG) -> 0 | CR5: =_xlfn.XLOOKUP(A5,VacPivot!A:A,VacPivot!AN:AN) -> 2 | CS5: {=SUM(IFERROR(CQ5:CR5,0))} -> 2
A6: Andrena.alleghaniensis | B6: =_xlfn.XLOOKUP(A6,PanPivot!A:A,PanPivot!B:B) -> 0 | C6: =_xlfn.XLOOKUP(A6,VacPivot!A:A,VacPivot!B:B) -> 0 | D6: {=SUM(IFERROR(B6:C6,0))} -> 0 | E6: =_xlfn.XLOOKUP(A6,PanPivot!A:A,PanPivot!C:C) -> 0 | F6: =_xlfn.XLOOKUP(A6,VacPivot!A:A,VacPivot!D:D) -> 0 | G6: {=SUM(IFERROR(E6:F6,0))} -> 0 | H6: =_xlfn.XLOOKUP(A6,PanPivot!A:A,PanPivot!D:D) -> 0 | I6: =_xlfn.XLOOKUP(A6,VacPivot!A:A,VacPivot!E:E) -> 0 | J6: {=SUM(IFERROR(H6:I6,0))} -> 0 | K6: =_xlfn.XLOOKUP(A6,PanPivot!A:A,PanPivot!E:E) -> 0 | L6: =_xlfn.XLOOKUP(Summing.bothpivots!A6,VacPivot!A:A,VacPivot!F:F) -> 0 | M6: {=SUM(IFERROR(K6:L6,0))} -> 0 | N6: =_xlfn.XLOOKUP(A6,PanPivot!A:A,PanPivot!F:F) -> 1 | O6: =_xlfn.XLOOKUP(A6,VacPivot!A:A,VacPivot!AO:AO) -> 0 | P6: {=SUM(IFERROR(N6:O6,0))} -> 1 | Q6: =_xlfn.XLOOKUP(A6,PanPivot!A:A,PanPivot!G:G) -> 0 | R6: =_xlfn.XLOOKUP(A6,VacPivot!A:A,VacPivot!H:H) -> 0 | S6: {=SUM(IFERROR(Q6:R6,0))} -> 0 | T6: =_xlfn.XLOOKUP(A6,PanPivot!A:A,PanPivot!H:H) -> 0 | U6: =_xlfn.XLOOKUP(A6,VacPivot!A:A,VacPivot!I:I) -> 0 | V6: {=SUM(IFERROR(T6:U6,0))} -> 0 | W6: =_xlfn.XLOOKUP(A6,PanPivot!A:A,PanPivot!I:I) -> 0 | X6: =_xlfn.XLOOKUP(A6,VacPivot!A:A,VacPivot!J:J) -> 0 | Y6: {=SUM(IFERROR(W6:X6,0))} -> 0 | Z6: =_xlfn.XLOOKUP(A6,PanPivot!A:A,PanPivot!J:J) -> 0 | AA6: =_xlfn.XLOOKUP(A6,VacPivot!A:A,VacPivot!K:K) -> 0 | AB6: {=SUM(IFERROR(Z6:AA6,0))} -> 0 | AC6: =_xlfn.XLOOKUP(A6,PanPivot!A:A,PanPivot!K:K) -> 0 | AD6: =_xlfn.XLOOKUP(A6,VacPivot!A:A,VacPivot!M:M) -> 0 | AE6: {=SUM(IFERROR(AC6:AD6,0))} -> 0 | AF6: =_xlfn.XLOOKUP(A6,PanPivot!A:A,PanPivot!L:L) -> 0 | AG6: =_xlfn.XLOOKUP(A6,VacPivot!A:A,VacPivot!N:N) -> 0 | AH6: {=SUM(IFERROR(AF6:AG6,0))} -> 0 | AI6: =_xlfn.XLOOKUP(A6,PanPivot!A:A,PanPivot!M:M) -> 0 | AJ6: =_xlfn.XLOOKUP(A6,VacPivot!A:A,VacPivot!O:O) -> 0 | AK6: {=SUM(IFERROR(AI6:AJ6,0))} -> 0 | AL6: =_xlfn.XLOOKUP(A6,PanPivot!A:A,PanPivot!N:N) -> 0 | AM6: =_xlfn.XLOOKUP(A6,VacPivot!A:A,VacPivot!P:P) -> 0 | AN6: {=SUM(IFERROR(AL6:AM6,0))} -> 0 | AO6: =_xlfn.XLOOKUP(A6,PanPivot!A:A,PanPivot!O:O) -> 0 | AP6: =_xlfn.XLOOKUP(A6,VacPivot!A:A,VacPivot!R:R) -> 0 | AQ6: {=SUM(IFERROR(AO6:AP6,0))} -> 0 | AR6: =_xlfn.XLOOKUP(A6,PanPivot!A:A,PanPivot!P:P) -> 0 | AS6: =_xlfn.XLOOKUP(A6,VacPivot!A:A,VacPivot!S:S) -> 0 | AT6: {=SUM(IFERROR(AR6:AS6,0))} -> 0 | AU6: =_xlfn.XLOOKUP(A6,PanPivot!A:A,PanPivot!Q:Q) -> 0 | AV6: =_xlfn.XLOOKUP(A6,VacPivot!A:A,VacPivot!T:T) -> 0 | AW6: {=SUM(IFERROR(AU6:AV6,0))} -> 0 | AX6: =_xlfn.XLOOKUP(A6,PanPivot!A:A,PanPivot!R:R) -> 2 | AY6: =_xlfn.XLOOKUP(A6,VacPivot!A:A,VacPivot!U:U) -> 0 | AZ6: {=SUM(IFERROR(AX6:AY6,0))} -> 2 | BA6: =_xlfn.XLOOKUP(A6,PanPivot!A:A,PanPivot!S:S) -> 0 | BB6: =_xlfn.XLOOKUP(A6,VacPivot!A:A,VacPivot!W:W) -> 1 | BC6: {=SUM(IFERROR(BA6:BB6,0))} -> 1 | BD6: =_xlfn.XLOOKUP(A6,PanPivot!A:A,PanPivot!T:T) -> 0 | BE6: =_xlfn.XLOOKUP(A6,VacPivot!A:A,VacPivot!X:X) -> 0 | BF6: {=SUM(IFERROR(BD6:BE6,0))} -> 0 | BG6: =_xlfn.XLOOKUP(A6,PanPivot!A:A,PanPivot!U:U) -> 0 | BH6: =_xlfn.XLOOKUP(Summing.bothpivots!A6,VacPivot!A:A,VacPivot!Y:Y) -> 0 | BI6: {=SUM(IFERROR(BG6:BH6,0))} -> 0 | BJ6: =_xlfn.XLOOKUP(A6,PanPivot!A:A,PanPivot!V:V) -> 0 | BK6: =_xlfn.XLOOKUP(A6,VacPivot!A:A,VacPivot!Z:Z) -> 0 | BL6: {=SUM(IFERROR(BJ6:BK6,0))} -> 0 | BM6: =_xlfn.XLOOKUP(A6,PanPivot!A:A,PanPivot!W:W) -> 0 | BN6: =_xlfn.XLOOKUP(A6,VacPivot!A:A,VacPivot!AB:AB) -> 0 | BO6: {=SUM(IFERROR(BM6:BN6,0))} -> 0 | BP6: =_xlfn.XLOOKUP(A6,PanPivot!A:A,PanPivot!X:X) -> 0 | BQ6: =_xlfn.XLOOKUP(A6,VacPivot!A:A,VacPivot!AC:AC) -> 0 | BR6: {=SUM(IFERROR(BP6:BQ6,0))} -> 0 | BS6: =_xlfn.XLOOKUP(Summing.bothpivots!A6,PanPivot!A:A,PanPivot!Y:Y) -> 1 | BT6: =_xlfn.XLOOKUP(A6,VacPivot!A:A,VacPivot!AD:AD) -> 0 | BU6: {=SUM(IFERROR(BS6:BT6,0))} -> 1 | BV6: =_xlfn.XLOOKUP(A6,PanPivot!A:A,PanPivot!Z:Z) -> 0 | BW6: =_xlfn.XLOOKUP(A6,VacPivot!A:A,VacPivot!AE:AE) -> 0 | BX6: {=SUM(IFERROR(BV6:BW6,0))} -> 0 | BY6: =_xlfn.XLOOKUP(A6,PanPivot!A:A,PanPivot!AA:AA) -> 0 | BZ6: =_xlfn.XLOOKUP(A6,VacPivot!A:A,VacPivot!AG:AG) -> 0 | CA6: {=SUM(IFERROR(BY6:BZ6,0))} -> 0 | CB6: =_xlfn.XLOOKUP(A6,PanPivot!A:A,PanPivot!AB:AB) -> 0 | CC6: =_xlfn.XLOOKUP(A6,VacPivot!A:A,VacPivot!AH:AH) -> 0 | CD6: {=SUM(IFERROR(CB6:CC6,0))} -> 0 | CE6: =_xlfn.XLOOKUP(A6,PanPivot!A:A,PanPivot!AC:AC) -> 0 | CF6: =_xlfn.XLOOKUP(A6,VacPivot!A:A,VacPivot!AI:AI) -> 0 | CG6: {=SUM(IFERROR(CE6:CF6,0))} -> 0 | CH6: =_xlfn.XLOOKUP(A6,PanPivot!A:A,PanPivot!AD:AD) -> 0 | CI6: =_xlfn.XLOOKUP(A6,VacPivot!A:A,VacPivot!AJ:AJ) -> 0 | CJ6: {=SUM(IFERROR(CH6:CI6,0))} -> 0 | CK6: =_xlfn.XLOOKUP(A6,PanPivot!A:A,PanPivot!AE:AE) -> 0 | CL6: =_xlfn.XLOOKUP(A6,VacPivot!A:A,VacPivot!AL:AL) -> 0 | CM6: {=SUM(IFERROR(CK6:CL6,0))} -> 0 | CN6: =_xlfn.XLOOKUP(A6,PanPivot!A:A,PanPivot!AF:AF) -> 0 | CO6: =_xlfn.XLOOKUP(A6,VacPivot!A:A,VacPivot!AM:AM) -> 0 | CP6: {=SUM(IFERROR(CN6:CO6,0))} -> 0 | CQ6: =_xlfn.XLOOKUP(A6,PanPivot!A:A,PanPivot!AG:AG) -> 0 | CR6: =_xlfn.XLOOKUP(A6,VacPivot!A:A,VacPivot!AN:AN) -> 0 | CS6: {=SUM(IFERROR(CQ6:CR6,0))} -> 0
A7: Andrena.asteris | B7: =_xlfn.XLOOKUP(A7,PanPivot!A:A,PanPivot!B:B) -> #N/A | C7: =_xlfn.XLOOKUP(A7,VacPivot!A:A,VacPivot!B:B) -> 0 | D7: {=SUM(IFERROR(B7:C7,0))} -> 0 | E7: =_xlfn.XLOOKUP(A7,PanPivot!A:A,PanPivot!C:C) -> #N/A | F7: =_xlfn.XLOOKUP(A7,VacPivot!A:A,VacPivot!D:D) -> 0 | G7: {=SUM(IFERROR(E7:F7,0))} -> 0 | H7: =_xlfn.XLOOKUP(A7,PanPivot!A:A,PanPivot!D:D) -> #N/A | I7: =_xlfn.XLOOKUP(A7,VacPivot!A:A,VacPivot!E:E) -> 1 | J7: {=SUM(IFERROR(H7:I7,0))} -> 1 | K7: =_xlfn.XLOOKUP(A7,PanPivot!A:A,PanPivot!E:E) -> #N/A | L7: =_xlfn.XLOOKUP(Summing.bothpivots!A7,VacPivot!A:A,VacPivot!F:F) -> 0 | M7: {=SUM(IFERROR(K7:L7,0))} -> 0 | N7: =_xlfn.XLOOKUP(A7,PanPivot!A:A,PanPivot!F:F) -> #N/A | O7: =_xlfn.XLOOKUP(A7,VacPivot!A:A,VacPivot!AO:AO) -> 0 | P7: {=SUM(IFERROR(N7:O7,0))} -> 0 | Q7: =_xlfn.XLOOKUP(A7,PanPivot!A:A,PanPivot!G:G) -> #N/A | R7: =_xlfn.XLOOKUP(A7,VacPivot!A:A,VacPivot!H:H) -> 0 | S7: {=SUM(IFERROR(Q7:R7,0))} -> 0 | T7: =_xlfn.XLOOKUP(A7,PanPivot!A:A,PanPivot!H:H) -> #N/A | U7: =_xlfn.XLOOKUP(A7,VacPivot!A:A,VacPivot!I:I) -> 0 | V7: {=SUM(IFERROR(T7:U7,0))} -> 0 | W7: =_xlfn.XLOOKUP(A7,PanPivot!A:A,PanPivot!I:I) -> #N/A | X7: =_xlfn.XLOOKUP(A7,VacPivot!A:A,VacPivot!J:J) -> 0 | Y7: {=SUM(IFERROR(W7:X7,0))} -> 0 | Z7: =_xlfn.XLOOKUP(A7,PanPivot!A:A,PanPivot!J:J) -> #N/A | AA7: =_xlfn.XLOOKUP(A7,VacPivot!A:A,VacPivot!K:K) -> 0 | AB7: {=SUM(IFERROR(Z7:AA7,0))} -> 0 | AC7: =_xlfn.XLOOKUP(A7,PanPivot!A:A,PanPivot!K:K) -> #N/A | AD7: =_xlfn.XLOOKUP(A7,VacPivot!A:A,VacPivot!M:M) -> 0 | AE7: {=SUM(IFERROR(AC7:AD7,0))} -> 0 | AF7: =_xlfn.XLOOKUP(A7,PanPivot!A:A,PanPivot!L:L) -> #N/A | AG7: =_xlfn.XLOOKUP(A7,VacPivot!A:A,VacPivot!N:N) -> 0 | AH7: {=SUM(IFERROR(AF7:AG7,0))} -> 0 | AI7: =_xlfn.XLOOKUP(A7,PanPivot!A:A,PanPivot!M:M) -> #N/A | AJ7: =_xlfn.XLOOKUP(A7,VacPivot!A:A,VacPivot!O:O) -> 0 | AK7: {=SUM(IFERROR(AI7:AJ7,0))} -> 0 | AL7: =_xlfn.XLOOKUP(A7,PanPivot!A:A,PanPivot!N:N) -> #N/A | AM7: =_xlfn.XLOOKUP(A7,VacPivot!A:A,VacPivot!P:P) -> 0 | AN7: {=SUM(IFERROR(AL7:AM7,0))} -> 0 | AO7: =_xlfn.XLOOKUP(A7,PanPivot!A:A,PanPivot!O:O) -> #N/A | AP7: =_xlfn.XLOOKUP(A7,VacPivot!A:A,VacPivot!R:R) -> 0 | AQ7: {=SUM(IFERROR(AO7:AP7,0))} -> 0 | AR7: =_xlfn.XLOOKUP(A7,PanPivot!A:A,PanPivot!P:P) -> #N/A | AS7: =_xlfn.XLOOKUP(A7,VacPivot!A:A,VacPivot!S:S) -> 0 | AT7: {=SUM(IFERROR(AR7:AS7,0))} -> 0 | AU7: =_xlfn.XLOOKUP(A7,PanPivot!A:A,PanPivot!Q:Q) -> #N/A | AV7: =_xlfn.XLOOKUP(A7,VacPivot!A:A,VacPivot!T:T) -> 0 | AW7: {=SUM(IFERROR(AU7:AV7,0))} -> 0 | AX7: =_xlfn.XLOOKUP(A7,PanPivot!A:A,PanPivot!R:R) -> #N/A | AY7: =_xlfn.XLOOKUP(A7,VacPivot!A:A,VacPivot!U:U) -> 0 | AZ7: {=SUM(IFERROR(AX7:AY7,0))} -> 0 | BA7: =_xlfn.XLOOKUP(A7,PanPivot!A:A,PanPivot!S:S) -> #N/A | BB7: =_xlfn.XLOOKUP(A7,VacPivot!A:A,VacPivot!W:W) -> 0 | BC7: {=SUM(IFERROR(BA7:BB7,0))} -> 0 | BD7: =_xlfn.XLOOKUP(A7,PanPivot!A:A,PanPivot!T:T) -> #N/A | BE7: =_xlfn.XLOOKUP(A7,VacPivot!A:A,VacPivot!X:X) -> 0 | BF7: {=SUM(IFERROR(BD7:BE7,0))} -> 0 | BG7: =_xlfn.XLOOKUP(A7,PanPivot!A:A,PanPivot!U:U) -> #N/A | BH7: =_xlfn.XLOOKUP(Summing.bothpivots!A7,VacPivot!A:A,VacPivot!Y:Y) -> 0 | BI7: {=SUM(IFERROR(BG7:BH7,0))} -> 0 | BJ7: =_xlfn.XLOOKUP(A7,PanPivot!A:A,PanPivot!V:V) -> #N/A | BK7: =_xlfn.XLOOKUP(A7,VacPivot!A:A,VacPivot!Z:Z) -> 0 | BL7: {=SUM(IFERROR(BJ7:BK7,0))} -> 0 | BM7: =_xlfn.XLOOKUP(A7,PanPivot!A:A,PanPivot!W:W) -> #N/A | BN7: =_xlfn.XLOOKUP(A7,VacPivot!A:A,VacPivot!AB:AB) -> 0 | BO7: {=SUM(IFERROR(BM7:BN7,0))} -> 0 | BP7: =_xlfn.XLOOKUP(A7,PanPivot!A:A,PanPivot!X:X) -> #N/A | BQ7: =_xlfn.XLOOKUP(A7,VacPivot!A:A,VacPivot!AC:AC) -> 0 | BR7: {=SUM(IFERROR(BP7:BQ7,0))} -> 0 | BS7: =_xlfn.XLOOKUP(Summing.bothpivots!A7,PanPivot!A:A,PanPivot!Y:Y) -> #N/A | BT7: =_xlfn.XLOOKUP(A7,VacPivot!A:A,VacPivot!AD:AD) -> 0 | BU7: {=SUM(IFERROR(BS7:BT7,0))} -> 0 | BV7: =_xlfn.XLOOKUP(A7,PanPivot!A:A,PanPivot!Z:Z) -> #N/A | BW7: =_xlfn.XLOOKUP(A7,VacPivot!A:A,VacPivot!AE:AE) -> 0 | BX7: {=SUM(IFERROR(BV7:BW7,0))} -> 0 | BY7: =_xlfn.XLOOKUP(A7,PanPivot!A:A,PanPivot!AA:AA) -> #N/A | BZ7: =_xlfn.XLOOKUP(A7,VacPivot!A:A,VacPivot!AG:AG) -> 0 | CA7: {=SUM(IFERROR(BY7:BZ7,0))} -> 0 | CB7: =_xlfn.XLOOKUP(A7,PanPivot!A:A,PanPivot!AB:AB) -> #N/A | CC7: =_xlfn.XLOOKUP(A7,VacPivot!A:A,VacPivot!AH:AH) -> 0 | CD7: {=SUM(IFERROR(CB7:CC7,0))} -> 0 | CE7: =_xlfn.XLOOKUP(A7,PanPivot!A:A,PanPivot!AC:AC) -> #N/A | CF7: =_xlfn.XLOOKUP(A7,VacPivot!A:A,VacPivot!AI:AI) -> 0 | CG7: {=SUM(IFERROR(CE7:CF7,0))} -> 0 | CH7: =_xlfn.XLOOKUP(A7,PanPivot!A:A,PanPivot!AD:AD) -> #N/A | CI7: =_xlfn.XLOOKUP(A7,VacPivot!A:A,VacPivot!AJ:AJ) -> 0 | CJ7: {=SUM(IFERROR(CH7:CI7,0))} -> 0 | CK7: =_xlfn.XLOOKUP(A7,PanPivot!A:A,PanPivot!AE:AE) -> #N/A | CL7: =_xlfn.XLOOKUP(A7,VacPivot!A:A,VacPivot!AL:AL) -> 0 | CM7: {=SUM(IFERROR(CK7:CL7,0))} -> 0 | CN7: =_xlfn.XLOOKUP(A7,PanPivot!A:A,PanPivot!AF:AF) -> #N/A | CO7: =_xlfn.XLOOKUP(A7,VacPivot!A:A,VacPivot!AM:AM) -> 0 | CP7: {=SUM(IFERROR(CN7:CO7,0))} -> 0 | CQ7: =_xlfn.XLOOKUP(A7,PanPivot!A:A,PanPivot!AG:AG) -> #N/A | CR7: =_xlfn.XLOOKUP(A7,VacPivot!A:A,VacPivot!AN:AN) -> 0 | CS7: {=SUM(IFERROR(CQ7:CR7,0))} -> 0
A8: Andrena.commoda | B8: =_xlfn.XLOOKUP(A8,PanPivot!A:A,PanPivot!B:B) -> 0 | C8: =_xlfn.XLOOKUP(A8,VacPivot!A:A,VacPivot!B:B) -> #N/A | D8: {=SUM(IFERROR(B8:C8,0))} -> 0 | E8: =_xlfn.XLOOKUP(A8,PanPivot!A:A,PanPivot!C:C) -> 0 | F8: =_xlfn.XLOOKUP(A8,VacPivot!A:A,VacPivot!D:D) -> #N/A | G8: {=SUM(IFERROR(E8:F8,0))} -> 0 | H8: =_xlfn.XLOOKUP(A8,PanPivot!A:A,PanPivot!D:D) -> 0 | I8: =_xlfn.XLOOKUP(A8,VacPivot!A:A,VacPivot!E:E) -> #N/A | J8: {=SUM(IFERROR(H8:I8,0))} -> 0 | K8: =_xlfn.XLOOKUP(A8,PanPivot!A:A,PanPivot!E:E) -> 0 | L8: =_xlfn.XLOOKUP(Summing.bothpivots!A8,VacPivot!A:A,VacPivot!F:F) -> #N/A | M8: {=SUM(IFERROR(K8:L8,0))} -> 0 | N8: =_xlfn.XLOOKUP(A8,PanPivot!A:A,PanPivot!F:F) -> 0 | O8: =_xlfn.XLOOKUP(A8,VacPivot!A:A,VacPivot!AO:AO) -> #N/A | P8: {=SUM(IFERROR(N8:O8,0))} -> 0 | Q8: =_xlfn.XLOOKUP(A8,PanPivot!A:A,PanPivot!G:G) -> 0 | R8: =_xlfn.XLOOKUP(A8,VacPivot!A:A,VacPivot!H:H) -> #N/A | S8: {=SUM(IFERROR(Q8:R8,0))} -> 0 | T8: =_xlfn.XLOOKUP(A8,PanPivot!A:A,PanPivot!H:H) -> 0 | U8: =_xlfn.XLOOKUP(A8,VacPivot!A:A,VacPivot!I:I) -> #N/A | V8: {=SUM(IFERROR(T8:U8,0))} -> 0 | W8: =_xlfn.XLOOKUP(A8,PanPivot!A:A,PanPivot!I:I) -> 0 | X8: =_xlfn.XLOOKUP(A8,VacPivot!A:A,VacPivot!J:J) -> #N/A | Y8: {=SUM(IFERROR(W8:X8,0))} -> 0 | Z8: =_xlfn.XLOOKUP(A8,PanPivot!A:A,PanPivot!J:J) -> 0 | AA8: =_xlfn.XLOOKUP(A8,VacPivot!A:A,VacPivot!K:K) -> #N/A | AB8: {=SUM(IFERROR(Z8:AA8,0))} -> 0 | AC8: =_xlfn.XLOOKUP(A8,PanPivot!A:A,PanPivot!K:K) -> 0 | AD8: =_xlfn.XLOOKUP(A8,VacPivot!A:A,VacPivot!M:M) -> #N/A | AE8: {=SUM(IFERROR(AC8:AD8,0))} -> 0 | AF8: =_xlfn.XLOOKUP(A8,PanPivot!A:A,PanPivot!L:L) -> 0 | AG8: =_xlfn.XLOOKUP(A8,VacPivot!A:A,VacPivot!N:N) -> #N/A | AH8: {=SUM(IFERROR(AF8:AG8,0))} -> 0 | AI8: =_xlfn.XLOOKUP(A8,PanPivot!A:A,PanPivot!M:M) -> 0 | AJ8: =_xlfn.XLOOKUP(A8,VacPivot!A:A,VacPivot!O:O) -> #N/A | AK8: {=SUM(IFERROR(AI8:AJ8,0))} -> 0 | AL8: =_xlfn.XLOOKUP(A8,PanPivot!A:A,PanPivot!N:N) -> 0 | AM8: =_xlfn.XLOOKUP(A8,VacPivot!A:A,VacPivot!P:P) -> #N/A | AN8: {=SUM(IFERROR(AL8:AM8,0))} -> 0 | AO8: =_xlfn.XLOOKUP(A8,PanPivot!A:A,PanPivot!O:O) -> 0 | AP8: =_xlfn.XLOOKUP(A8,VacPivot!A:A,VacPivot!R:R) -> #N/A | AQ8: {=SUM(IFERROR(AO8:AP8,0))} -> 0 | AR8: =_xlfn.XLOOKUP(A8,PanPivot!A:A,PanPivot!P:P) -> 0 | AS8: =_xlfn.XLOOKUP(A8,VacPivot!A:A,VacPivot!S:S) -> #N/A | AT8: {=SUM(IFERROR(AR8:AS8,0))} -> 0 | AU8: =_xlfn.XLOOKUP(A8,PanPivot!A:A,PanPivot!Q:Q) -> 0 | AV8: =_xlfn.XLOOKUP(A8,VacPivot!A:A,VacPivot!T:T) -> #N/A | AW8: {=SUM(IFERROR(AU8:AV8,0))} -> 0 | AX8: =_xlfn.XLOOKUP(A8,PanPivot!A:A,PanPivot!R:R) -> 0 | AY8: =_xlfn.XLOOKUP(A8,VacPivot!A:A,VacPivot!U:U) -> #N/A | AZ8: {=SUM(IFERROR(AX8:AY8,0))} -> 0 | BA8: =_xlfn.XLOOKUP(A8,PanPivot!A:A,PanPivot!S:S) -> 1 | BB8: =_xlfn.XLOOKUP(A8,VacPivot!A:A,VacPivot!W:W) -> #N/A | BC8: {=SUM(IFERROR(BA8:BB8,0))} -> 1 | BD8: =_xlfn.XLOOKUP(A8,PanPivot!A:A,PanPivot!T:T) -> 0 | BE8: =_xlfn.XLOOKUP(A8,VacPivot!A:A,VacPivot!X:X) -> #N/A | BF8: {=SUM(IFERROR(BD8:BE8,0))} -> 0 | BG8: =_xlfn.XLOOKUP(A8,PanPivot!A:A,PanPivot!U:U) -> 0 | BH8: =_xlfn.XLOOKUP(Summing.bothpivots!A8,VacPivot!A:A,VacPivot!Y:Y) -> #N/A | BI8: {=SUM(IFERROR(BG8:BH8,0))} -> 0 | BJ8: =_xlfn.XLOOKUP(A8,PanPivot!A:A,PanPivot!V:V) -> 0 | BK8: =_xlfn.XLOOKUP(A8,VacPivot!A:A,VacPivot!Z:Z) -> #N/A | BL8: {=SUM(IFERROR(BJ8:BK8,0))} -> 0 | BM8: =_xlfn.XLOOKUP(A8,PanPivot!A:A,PanPivot!W:W) -> 0 | BN8: =_xlfn.XLOOKUP(A8,VacPivot!A:A,VacPivot!AB:AB) -> #N/A | BO8: {=SUM(IFERROR(BM8:BN8,0))} -> 0 | BP8: =_xlfn.XLOOKUP(A8,PanPivot!A:A,PanPivot!X:X) -> 0 | BQ8: =_xlfn.XLOOKUP(A8,VacPivot!A:A,VacPivot!AC:AC) -> #N/A | BR8: {=SUM(IFERROR(BP8:BQ8,0))} -> 0 | BS8: =_xlfn.XLOOKUP(Summing.bothpivots!A8,PanPivot!A:A,PanPivot!Y:Y) -> 0 | BT8: =_xlfn.XLOOKUP(A8,VacPivot!A:A,VacPivot!AD:AD) -> #N/A | BU8: {=SUM(IFERROR(BS8:BT8,0))} -> 0 | BV8: =_xlfn.XLOOKUP(A8,PanPivot!A:A,PanPivot!Z:Z) -> 0 | BW8: =_xlfn.XLOOKUP(A8,VacPivot!A:A,VacPivot!AE:AE) -> #N/A | BX8: {=SUM(IFERROR(BV8:BW8,0))} -> 0 | BY8: =_xlfn.XLOOKUP(A8,PanPivot!A:A,PanPivot!AA:AA) -> 0 | BZ8: =_xlfn.XLOOKUP(A8,VacPivot!A:A,VacPivot!AG:AG) -> #N/A | CA8: {=SUM(IFERROR(BY8:BZ8,0))} -> 0 | CB8: =_xlfn.XLOOKUP(A8,PanPivot!A:A,PanPivot!AB:AB) -> 0 | CC8: =_xlfn.XLOOKUP(A8,VacPivot!A:A,VacPivot!AH:AH) -> #N/A | CD8: {=SUM(IFERROR(CB8:CC8,0))} -> 0 | CE8: =_xlfn.XLOOKUP(A8,PanPivot!A:A,PanPivot!AC:AC) -> 0 | CF8: =_xlfn.XLOOKUP(A8,VacPivot!A:A,VacPivot!AI:AI) -> #N/A | CG8: {=SUM(IFERROR(CE8:CF8,0))} -> 0 | CH8: =_xlfn.XLOOKUP(A8,PanPivot!A:A,PanPivot!AD:AD) -> 0 | CI8: =_xlfn.XLOOKUP(A8,VacPivot!A:A,VacPivot!AJ:AJ) -> #N/A | CJ8: {=SUM(IFERROR(CH8:CI8,0))} -> 0 | CK8: =_xlfn.XLOOKUP(A8,PanPivot!A:A,PanPivot!AE:AE) -> 0 | CL8: =_xlfn.XLOOKUP(A8,VacPivot!A:A,VacPivot!AL:AL) -> #N/A | CM8: {=SUM(IFERROR(CK8:CL8,0))} -> 0 | CN8: =_xlfn.XLOOKUP(A8,PanPivot!A:A,PanPivot!AF:AF) -> 0 | CO8: =_xlfn.XLOOKUP(A8,VacPivot!A:A,VacPivot!AM:AM) -> #N/A | CP8: {=SUM(IFERROR(CN8:CO8,0))} -> 0 | CQ8: =_xlfn.XLOOKUP(A8,PanPivot!A:A,PanPivot!AG:AG) -> 0 | CR8: =_xlfn.XLOOKUP(A8,VacPivot!A:A,VacPivot!AN:AN) -> #N/A | CS8: {=SUM(IFERROR(CQ8:CR8,0))} -> 0
A9: Andrena.miserabilis | B9: =_xlfn.XLOOKUP(A9,PanPivot!A:A,PanPivot!B:B) -> 0 | C9: =_xlfn.XLOOKUP(A9,VacPivot!A:A,VacPivot!B:B) -> #N/A | D9: {=SUM(IFERROR(B9:C9,0))} -> 0 | E9: =_xlfn.XLOOKUP(A9,PanPivot!A:A,PanPivot!C:C) -> 0 | F9: =_xlfn.XLOOKUP(A9,VacPivot!A:A,VacPivot!D:D) -> #N/A | G9: {=SUM(IFERROR(E9:F9,0))} -> 0 | H9: =_xlfn.XLOOKUP(A9,PanPivot!A:A,PanPivot!D:D) -> 0 | I9: =_xlfn.XLOOKUP(A9,VacPivot!A:A,VacPivot!E:E) -> #N/A | J9: {=SUM(IFERROR(H9:I9,0))} -> 0 | K9: =_xlfn.XLOOKUP(A9,PanPivot!A:A,PanPivot!E:E) -> 0 | L9: =_xlfn.XLOOKUP(Summing.bothpivots!A9,VacPivot!A:A,VacPivot!F:F) -> #N/A | M9: {=SUM(IFERROR(K9:L9,0))} -> 0 | N9: =_xlfn.XLOOKUP(A9,PanPivot!A:A,PanPivot!F:F) -> 1 | O9: =_xlfn.XLOOKUP(A9,VacPivot!A:A,VacPivot!AO:AO) -> #N/A | P9: {=SUM(IFERROR(N9:O9,0))} -> 1 | Q9: =_xlfn.XLOOKUP(A9,PanPivot!A:A,PanPivot!G:G) -> 0 | R9: =_xlfn.XLOOKUP(A9,VacPivot!A:A,VacPivot!H:H) -> #N/A | S9: {=SUM(IFERROR(Q9:R9,0))} -> 0 | T9: =_xlfn.XLOOKUP(A9,PanPivot!A:A,PanPivot!H:H) -> 0 | U9: =_xlfn.XLOOKUP(A9,VacPivot!A:A,VacPivot!I:I) -> #N/A | V9: {=SUM(IFERROR(T9:U9,0))} -> 0 | W9: =_xlfn.XLOOKUP(A9,PanPivot!A:A,PanPivot!I:I) -> 0 | X9: =_xlfn.XLOOKUP(A9,VacPivot!A:A,VacPivot!J:J) -> #N/A | Y9: {=SUM(IFERROR(W9:X9,0))} -> 0 | Z9: =_xlfn.XLOOKUP(A9,PanPivot!A:A,PanPivot!J:J) -> 0 | AA9: =_xlfn.XLOOKUP(A9,VacPivot!A:A,VacPivot!K:K) -> #N/A | AB9: {=SUM(IFERROR(Z9:AA9,0))} -> 0 | AC9: =_xlfn.XLOOKUP(A9,PanPivot!A:A,PanPivot!K:K) -> 0 | AD9: =_xlfn.XLOOKUP(A9,VacPivot!A:A,VacPivot!M:M) -> #N/A | AE9: {=SUM(IFERROR(AC9:AD9,0))} -> 0 | AF9: =_xlfn.XLOOKUP(A9,PanPivot!A:A,PanPivot!L:L) -> 0 | AG9: =_xlfn.XLOOKUP(A9,VacPivot!A:A,VacPivot!N:N) -> #N/A | AH9: {=SUM(IFERROR(AF9:AG9,0))} -> 0 | AI9: =_xlfn.XLOOKUP(A9,PanPivot!A:A,PanPivot!M:M) -> 0 | AJ9: =_xlfn.XLOOKUP(A9,VacPivot!A:A,VacPivot!O:O) -> #N/A | AK9: {=SUM(IFERROR(AI9:AJ9,0))} -> 0 | AL9: =_xlfn.XLOOKUP(A9,PanPivot!A:A,PanPivot!N:N) -> 0 | AM9: =_xlfn.XLOOKUP(A9,VacPivot!A:A,VacPivot!P:P) -> #N/A | AN9: {=SUM(IFERROR(AL9:AM9,0))} -> 0 | AO9: =_xlfn.XLOOKUP(A9,PanPivot!A:A,PanPivot!O:O) -> 0 | AP9: =_xlfn.XLOOKUP(A9,VacPivot!A:A,VacPivot!R:R) -> #N/A | AQ9: {=SUM(IFERROR(AO9:AP9,0))} -> 0 | AR9: =_xlfn.XLOOKUP(A9,PanPivot!A:A,PanPivot!P:P) -> 0 | AS9: =_xlfn.XLOOKUP(A9,VacPivot!A:A,VacPivot!S:S) -> #N/A | AT9: {=SUM(IFERROR(AR9:AS9,0))} -> 0 | AU9: =_xlfn.XLOOKUP(A9,PanPivot!A:A,PanPivot!Q:Q) -> 0 | AV9: =_xlfn.XLOOKUP(A9,VacPivot!A:A,VacPivot!T:T) -> #N/A | AW9: {=SUM(IFERROR(AU9:AV9,0))} -> 0 | AX9: =_xlfn.XLOOKUP(A9,PanPivot!A:A,PanPivot!R:R) -> 0 | AY9: =_xlfn.XLOOKUP(A9,VacPivot!A:A,VacPivot!U:U) -> #N/A | AZ9: {=SUM(IFERROR(AX9:AY9,0))} -> 0 | BA9: =_xlfn.XLOOKUP(A9,PanPivot!A:A,PanPivot!S:S) -> 0 | BB9: =_xlfn.XLOOKUP(A9,VacPivot!A:A,VacPivot!W:W) -> #N/A | BC9: {=SUM(IFERROR(BA9:BB9,0))} -> 0 | BD9: =_xlfn.XLOOKUP(A9,PanPivot!A:A,PanPivot!T:T) -> 0 | BE9: =_xlfn.XLOOKUP(A9,VacPivot!A:A,VacPivot!X:X) -> #N/A | BF9: {=SUM(IFERROR(BD9:BE9,0))} -> 0 | BG9: =_xlfn.XLOOKUP(A9,PanPivot!A:A,PanPivot!U:U) -> 0 | BH9: =_xlfn.XLOOKUP(Summing.bothpivots!A9,VacPivot!A:A,VacPivot!Y:Y) -> #N/A | BI9: {=SUM(IFERROR(BG9:BH9,0))} -> 0 | BJ9: =_xlfn.XLOOKUP(A9,PanPivot!A:A,PanPivot!V:V) -> 0 | BK9: =_xlfn.XLOOKUP(A9,VacPivot!A:A,VacPivot!Z:Z) -> #N/A | BL9: {=SUM(IFERROR(BJ9:BK9,0))} -> 0 | BM9: =_xlfn.XLOOKUP(A9,PanPivot!A:A,PanPivot!W:W) -> 0 | BN9: =_xlfn.XLOOKUP(A9,VacPivot!A:A,VacPivot!AB:AB) -> #N/A | BO9: {=SUM(IFERROR(BM9:BN9,0))} -> 0 | BP9: =_xlfn.XLOOKUP(A9,PanPivot!A:A,PanPivot!X:X) -> 0 | BQ9: =_xlfn.XLOOKUP(A9,VacPivot!A:A,VacPivot!AC:AC) -> #N/A | BR9: {=SUM(IFERROR(BP9:BQ9,0))} -> 0 | BS9: =_xlfn.XLOOKUP(Summing.bothpivots!A9,PanPivot!A:A,PanPivot!Y:Y) -> 0 | BT9: =_xlfn.XLOOKUP(A9,VacPivot!A:A,VacPivot!AD:AD) -> #N/A | BU9: {=SUM(IFERROR(BS9:BT9,0))} -> 0 | BV9: =_xlfn.XLOOKUP(A9,PanPivot!A:A,PanPivot!Z:Z) -> 0 | BW9: =_xlfn.XLOOKUP(A9,VacPivot!A:A,VacPivot!AE:AE) -> #N/A | BX9: {=SUM(IFERROR(BV9:BW9,0))} -> 0 | BY9: =_xlfn.XLOOKUP(A9,PanPivot!A:A,PanPivot!AA:AA) -> 0 | BZ9: =_xlfn.XLOOKUP(A9,VacPivot!A:A,VacPivot!AG:AG) -> #N/A | CA9: {=SUM(IFERROR(BY9:BZ9,0))} -> 0 | CB9: =_xlfn.XLOOKUP(A9,PanPivot!A:A,PanPivot!AB:AB) -> 0 | CC9: =_xlfn.XLOOKUP(A9,VacPivot!A:A,VacPivot!AH:AH) -> #N/A | CD9: {=SUM(IFERROR(CB9:CC9,0))} -> 0 | CE9: =_xlfn.XLOOKUP(A9,PanPivot!A:A,PanPivot!AC:AC) -> 0 | CF9: =_xlfn.XLOOKUP(A9,VacPivot!A:A,VacPivot!AI:AI) -> #N/A | CG9: {=SUM(IFERROR(CE9:CF9,0))} -> 0 | CH9: =_xlfn.XLOOKUP(A9,PanPivot!A:A,PanPivot!AD:AD) -> 0 | CI9: =_xlfn.XLOOKUP(A9,VacPivot!A:A,VacPivot!AJ:AJ) -> #N/A | CJ9: {=SUM(IFERROR(CH9:CI9,0))} -> 0 | CK9: =_xlfn.XLOOKUP(A9,PanPivot!A:A,PanPivot!AE:AE) -> 0 | CL9: =_xlfn.XLOOKUP(A9,VacPivot!A:A,VacPivot!AL:AL) -> #N/A | CM9: {=SUM(IFERROR(CK9:CL9,0))} -> 0 | CN9: =_xlfn.XLOOKUP(A9,PanPivot!A:A,PanPivot!AF:AF) -> 0 | CO9: =_xlfn.XLOOKUP(A9,VacPivot!A:A,VacPivot!AM:AM) -> #N/A | CP9: {=SUM(IFERROR(CN9:CO9,0))} -> 0 | CQ9: =_xlfn.XLOOKUP(A9,PanPivot!A:A,PanPivot!AG:AG) -> 0 | CR9: =_xlfn.XLOOKUP(A9,VacPivot!A:A,VacPivot!AN:AN) -> #N/A | CS9: {=SUM(IFERROR(CQ9:CR9,0))} -> 0
A10: Andrena.nasonii | B10: =_xlfn.XLOOKUP(A10,PanPivot!A:A,PanPivot!B:B) -> 0 | C10: =_xlfn.XLOOKUP(A10,VacPivot!A:A,VacPivot!B:B) -> #N/A | D10: {=SUM(IFERROR(B10:C10,0))} -> 0 | E10: =_xlfn.XLOOKUP(A10,PanPivot!A:A,PanPivot!C:C) -> 0 | F10: =_xlfn.XLOOKUP(A10,VacPivot!A:A,VacPivot!D:D) -> #N/A | G10: {=SUM(IFERROR(E10:F10,0))} -> 0 | H10: =_xlfn.XLOOKUP(A10,PanPivot!A:A,PanPivot!D:D) -> 0 | I10: =_xlfn.XLOOKUP(A10,VacPivot!A:A,VacPivot!E:E) -> #N/A | J10: {=SUM(IFERROR(H10:I10,0))} -> 0 | K10: =_xlfn.XLOOKUP(A10,PanPivot!A:A,PanPivot!E:E) -> 0 | L10: =_xlfn.XLOOKUP(Summing.bothpivots!A10,VacPivot!A:A,VacPivot!F:F) -> #N/A | M10: {=SUM(IFERROR(K10:L10,0))} -> 0 | N10: =_xlfn.XLOOKUP(A10,PanPivot!A:A,PanPivot!F:F) -> 0 | O10: =_xlfn.XLOOKUP(A10,VacPivot!A:A,VacPivot!AO:AO) -> #N/A | P10: {=SUM(IFERROR(N10:O10,0))} -> 0 | Q10: =_xlfn.XLOOKUP(A10,PanPivot!A:A,PanPivot!G:G) -> 0 | R10: =_xlfn.XLOOKUP(A10,VacPivot!A:A,VacPivot!H:H) -> #N/A | S10: {=SUM(IFERROR(Q10:R10,0))} -> 0 | T10: =_xlfn.XLOOKUP(A10,PanPivot!A:A,PanPivot!H:H) -> 0 | U10: =_xlfn.XLOOKUP(A10,VacPivot!A:A,VacPivot!I:I) -> #N/A | V10: {=SUM(IFERROR(T10:U10,0))} -> 0 | W10: =_xlfn.XLOOKUP(A10,PanPivot!A:A,PanPivot!I:I) -> 0 | X10: =_xlfn.XLOOKUP(A10,VacPivot!A:A,VacPivot!J:J) -> #N/A | Y10: {=SUM(IFERROR(W10:X10,0))} -> 0 | Z10: =_xlfn.XLOOKUP(A10,PanPivot!A:A,PanPivot!J:J) -> 0 | AA10: =_xlfn.XLOOKUP(A10,VacPivot!A:A,VacPivot!K:K) -> #N/A | AB10: {=SUM(IFERROR(Z10:AA10,0))} -> 0 | AC10: =_xlfn.XLOOKUP(A10,PanPivot!A:A,PanPivot!K:K) -> 0 | AD10: =_xlfn.XLOOKUP(A10,VacPivot!A:A,VacPivot!M:M) -> #N/A | AE10: {=SUM(IFERROR(AC10:AD10,0))} -> 0 | AF10: =_xlfn.XLOOKUP(A10,PanPivot!A:A,PanPivot!L:L) -> 0 | AG10: =_xlfn.XLOOKUP(A10,VacPivot!A:A,VacPivot!N:N) -> #N/A | AH10: {=SUM(IFERROR(AF10:AG10,0))} -> 0 | AI10: =_xlfn.XLOOKUP(A10,PanPivot!A:A,PanPivot!M:M) -> 0 | AJ10: =_xlfn.XLOOKUP(A10,VacPivot!A:A,VacPivot!O:O) -> #N/A | AK10: {=SUM(IFERROR(AI10:AJ10,0))} -> 0 | AL10: =_xlfn.XLOOKUP(A10,PanPivot!A:A,PanPivot!N:N) -> 0 | AM10: =_xlfn.XLOOKUP(A10,VacPivot!A:A,VacPivot!P:P) -> #N/A | AN10: {=SUM(IFERROR(AL10:AM10,0))} -> 0 | AO10: =_xlfn.XLOOKUP(A10,PanPivot!A:A,PanPivot!O:O) -> 0 | AP10: =_xlfn.XLOOKUP(A10,VacPivot!A:A,VacPivot!R:R) -> #N/A | AQ10: {=SUM(IFERROR(AO10:AP10,0))} -> 0 | AR10: =_xlfn.XLOOKUP(A10,PanPivot!A:A,PanPivot!P:P) -> 0 | AS10: =_xlfn.XLOOKUP(A10,VacPivot!A:A,VacPivot!S:S) -> #N/A | AT10: {=SUM(IFERROR(AR10:AS10,0))} -> 0 | AU10: =_xlfn.XLOOKUP(A10,PanPivot!A:A,PanPivot!Q:Q) -> 0 | AV10: =_xlfn.XLOOKUP(A10,VacPivot!A:A,VacPivot!T:T) -> #N/A | AW10: {=SUM(IFERROR(AU10:AV10,0))} -> 0 | AX10: =_xlfn.XLOOKUP(A10,PanPivot!A:A,PanPivot!R:R) -> 1 | AY10: =_xlfn.XLOOKUP(A10,VacPivot!A:A,VacPivot!U:U) -> #N/A | AZ10: {=SUM(IFERROR(AX10:AY10,0))} -> 1 | BA10: =_xlfn.XLOOKUP(A10,PanPivot!A:A,PanPivot!S:S) -> 12 | BB10: =_xlfn.XLOOKUP(A10,VacPivot!A:A,VacPivot!W:W) -> #N/A | BC10: {=SUM(IFERROR(BA10:BB10,0))} -> 12 | BD10: =_xlfn.XLOOKUP(A10,PanPivot!A:A,PanPivot!T:T) -> 0 | BE10: =_xlfn.XLOOKUP(A10,VacPivot!A:A,VacPivot!X:X) -> #N/A | BF10: {=SUM(IFERROR(BD10:BE10,0))} -> 0 | BG10: =_xlfn.XLOOKUP(A10,PanPivot!A:A,PanPivot!U:U) -> 0 | BH10: =_xlfn.XLOOKUP(Summing.bothpivots!A10,VacPivot!A:A,VacPivot!Y:Y) -> #N/A | BI10: {=SUM(IFERROR(BG10:BH10,0))} -> 0 | BJ10: =_xlfn.XLOOKUP(A10,PanPivot!A:A,PanPivot!V:V) -> 0 | BK10: =_xlfn.XLOOKUP(A10,VacPivot!A:A,VacPivot!Z:Z) -> #N/A | BL10: {=SUM(IFERROR(BJ10:BK10,0))} -> 0 | BM10: =_xlfn.XLOOKUP(A10,PanPivot!A:A,PanPivot!W:W) -> 0 | BN10: =_xlfn.XLOOKUP(A10,VacPivot!A:A,VacPivot!AB:AB) -> #N/A | BO10: {=SUM(IFERROR(BM10:BN10,0))} -> 0 | BP10: =_xlfn.XLOOKUP(A10,PanPivot!A:A,PanPivot!X:X) -> 0 | BQ10: =_xlfn.XLOOKUP(A10,VacPivot!A:A,VacPivot!AC:AC) -> #N/A | BR10: {=SUM(IFERROR(BP10:BQ10,0))} -> 0 | BS10: =_xlfn.XLOOKUP(Summing.bothpivots!A10,PanPivot!A:A,PanPivot!Y:Y) -> 0 | BT10: =_xlfn.XLOOKUP(A10,VacPivot!A:A,VacPivot!AD:AD) -> #N/A | BU10: {=SUM(IFERROR(BS10:BT10,0))} -> 0 | BV10: =_xlfn.XLOOKUP(A10,PanPivot!A:A,PanPivot!Z:Z) -> 0 | BW10: =_xlfn.XLOOKUP(A10,VacPivot!A:A,VacPivot!AE:AE) -> #N/A | BX10: {=SUM(IFERROR(BV10:BW10,0))} -> 0 | BY10: =_xlfn.XLOOKUP(A10,PanPivot!A:A,PanPivot!AA:AA) -> 0 | BZ10: =_xlfn.XLOOKUP(A10,VacPivot!A:A,VacPivot!AG:AG) -> #N/A | CA10: {=SUM(IFERROR(BY10:BZ10,0))} -> 0 | CB10: =_xlfn.XLOOKUP(A10,PanPivot!A:A,PanPivot!AB:AB) -> 0 | CC10: =_xlfn.XLOOKUP(A10,VacPivot!A:A,VacPivot!AH:AH) -> #N/A | CD10: {=SUM(IFERROR(CB10:CC10,0))} -> 0 | CE10: =_xlfn.XLOOKUP(A10,PanPivot!A:A,PanPivot!AC:AC) -> 0 | CF10: =_xlfn.XLOOKUP(A10,VacPivot!A:A,VacPivot!AI:AI) -> #N/A | CG10: {=SUM(IFERROR(CE10:CF10,0))} -> 0 | CH10: =_xlfn.XLOOKUP(A10,PanPivot!A:A,PanPivot!AD:AD) -> 0 | CI10: =_xlfn.XLOOKUP(A10,VacPivot!A:A,VacPivot!AJ:AJ) -> #N/A | CJ10: {=SUM(IFERROR(CH10:CI10,0))} -> 0 | CK10: =_xlfn.XLOOKUP(A10,PanPivot!A:A,PanPivot!AE:AE) -> 0 | CL10: =_xlfn.XLOOKUP(A10,VacPivot!A:A,VacPivot!AL:AL) -> #N/A | CM10: {=SUM(IFERROR(CK10:CL10,0))} -> 0 | CN10: =_xlfn.XLOOKUP(A10,PanPivot!A:A,PanPivot!AF:AF) -> 0 | CO10: =_xlfn.XLOOKUP(A10,VacPivot!A:A,VacPivot!AM:AM) -> #N/A | CP10: {=SUM(IFERROR(CN10:CO10,0))} -> 0 | CQ10: =_xlfn.XLOOKUP(A10,PanPivot!A:A,PanPivot!AG:AG) -> 0 | CR10: =_xlfn.XLOOKUP(A10,VacPivot!A:A,VacPivot!AN:AN) -> #N/A | CS10: {=SUM(IFERROR(CQ10:CR10,0))} -> 0
A11: Andrena.vicina | B11: =_xlfn.XLOOKUP(A11,PanPivot!A:A,PanPivot!B:B) -> 0 | C11: =_xlfn.XLOOKUP(A11,VacPivot!A:A,VacPivot!B:B) -> 0 | D11: {=SUM(IFERROR(B11:C11,0))} -> 0 | E11: =_xlfn.XLOOKUP(A11,PanPivot!A:A,PanPivot!C:C) -> 0 | F11: =_xlfn.XLOOKUP(A11,VacPivot!A:A,VacPivot!D:D) -> 0 | G11: {=SUM(IFERROR(E11:F11,0))} -> 0 | H11: =_xlfn.XLOOKUP(A11,PanPivot!A:A,PanPivot!D:D) -> 0 | I11: =_xlfn.XLOOKUP(A11,VacPivot!A:A,VacPivot!E:E) -> 0 | J11: {=SUM(IFERROR(H11:I11,0))} -> 0 | K11: =_xlfn.XLOOKUP(A11,PanPivot!A:A,PanPivot!E:E) -> 0 | L11: =_xlfn.XLOOKUP(Summing.bothpivots!A11,VacPivot!A:A,VacPivot!F:F) -> 0 | M11: {=SUM(IFERROR(K11:L11,0))} -> 0 | N11: =_xlfn.XLOOKUP(A11,PanPivot!A:A,PanPivot!F:F) -> 0 | O11: =_xlfn.XLOOKUP(A11,VacPivot!A:A,VacPivot!AO:AO) -> 0 | P11: {=SUM(IFERROR(N11:O11,0))} -> 0 | Q11: =_xlfn.XLOOKUP(A11,PanPivot!A:A,PanPivot!G:G) -> 0 | R11: =_xlfn.XLOOKUP(A11,VacPivot!A:A,VacPivot!H:H) -> 0 | S11: {=SUM(IFERROR(Q11:R11,0))} -> 0 | T11: =_xlfn.XLOOKUP(A11,PanPivot!A:A,PanPivot!H:H) -> 0 | U11: =_xlfn.XLOOKUP(A11,VacPivot!A:A,VacPivot!I:I) -> 0 | V11: {=SUM(IFERROR(T11:U11,0))} -> 0 | W11: =_xlfn.XLOOKUP(A11,PanPivot!A:A,PanPivot!I:I) -> 0 | X11: =_xlfn.XLOOKUP(A11,VacPivot!A:A,VacPivot!J:J) -> 0 | Y11: {=SUM(IFERROR(W11:X11,0))} -> 0 | Z11: =_xlfn.XLOOKUP(A11,PanPivot!A:A,PanPivot!J:J) -> 0 | AA11: =_xlfn.XLOOKUP(A11,VacPivot!A:A,VacPivot!K:K) -> 0 | AB11: {=SUM(IFERROR(Z11:AA11,0))} -> 0 | AC11: =_xlfn.XLOOKUP(A11,PanPivot!A:A,PanPivot!K:K) -> 0 | AD11: =_xlfn.XLOOKUP(A11,VacPivot!A:A,VacPivot!M:M) -> 0 | AE11: {=SUM(IFERROR(AC11:AD11,0))} -> 0 | AF11: =_xlfn.XLOOKUP(A11,PanPivot!A:A,PanPivot!L:L) -> 0 | AG11: =_xlfn.XLOOKUP(A11,VacPivot!A:A,VacPivot!N:N) -> 0 | AH11: {=SUM(IFERROR(AF11:AG11,0))} -> 0 | AI11: =_xlfn.XLOOKUP(A11,PanPivot!A:A,PanPivot!M:M) -> 0 | AJ11: =_xlfn.XLOOKUP(A11,VacPivot!A:A,VacPivot!O:O) -> 0 | AK11: {=SUM(IFERROR(AI11:AJ11,0))} -> 0 | AL11: =_xlfn.XLOOKUP(A11,PanPivot!A:A,PanPivot!N:N) -> 0 | AM11: =_xlfn.XLOOKUP(A11,VacPivot!A:A,VacPivot!P:P) -> 0 | AN11: {=SUM(IFERROR(AL11:AM11,0))} -> 0 | AO11: =_xlfn.XLOOKUP(A11,PanPivot!A:A,PanPivot!O:O) -> 0 | AP11: =_xlfn.XLOOKUP(A11,VacPivot!A:A,VacPivot!R:R) -> 0 | AQ11: {=SUM(IFERROR(AO11:AP11,0))} -> 0 | AR11: =_xlfn.XLOOKUP(A11,PanPivot!A:A,PanPivot!P:P) -> 0 | AS11: =_xlfn.XLOOKUP(A11,VacPivot!A:A,VacPivot!S:S) -> 0 | AT11: {=SUM(IFERROR(AR11:AS11,0))} -> 0 | AU11: =_xlfn.XLOOKUP(A11,PanPivot!A:A,PanPivot!Q:Q) -> 0 | AV11: =_xlfn.XLOOKUP(A11,VacPivot!A:A,VacPivot!T:T) -> 0 | AW11: {=SUM(IFERROR(AU11:AV11,0))} -> 0 | AX11: =_xlfn.XLOOKUP(A11,PanPivot!A:A,PanPivot!R:R) -> 0 | AY11: =_xlfn.XLOOKUP(A11,VacPivot!A:A,VacPivot!U:U) -> 0 | AZ11: {=SUM(IFERROR(AX11:AY11,0))} -> 0 | BA11: =_xlfn.XLOOKUP(A11,PanPivot!A:A,PanPivot!S:S) -> 1 | BB11: =_xlfn.XLOOKUP(A11,VacPivot!A:A,VacPivot!W:W) -> 0 | BC11: {=SUM(IFERROR(BA11:BB11,0))} -> 1 | BD11: =_xlfn.XLOOKUP(A11,PanPivot!A:A,PanPivot!T:T) -> 0 | BE11: =_xlfn.XLOOKUP(A11,VacPivot!A:A,VacPivot!X:X) -> 1 | BF11: {=SUM(IFERROR(BD11:BE11,0))} -> 1 | BG11: =_xlfn.XLOOKUP(A11,PanPivot!A:A,PanPivot!U:U) -> 0 | BH11: =_xlfn.XLOOKUP(Summing.bothpivots!A11,VacPivot!A:A,VacPivot!Y:Y) -> 0 | BI11: {=SUM(IFERROR(BG11:BH11,0))} -> 0 | BJ11: =_xlfn.XLOOKUP(A11,PanPivot!A:A,PanPivot!V:V) -> 0 | BK11: =_xlfn.XLOOKUP(A11,VacPivot!A:A,VacPivot!Z:Z) -> 0 | BL11: {=SUM(IFERROR(BJ11:BK11,0))} -> 0 | BM11: =_xlfn.XLOOKUP(A11,PanPivot!A:A,PanPivot!W:W) -> 0 | BN11: =_xlfn.XLOOKUP(A11,VacPivot!A:A,VacPivot!AB:AB) -> 0 | BO11: {=SUM(IFERROR(BM11:BN11,0))} -> 0 | BP11: =_xlfn.XLOOKUP(A11,PanPivot!A:A,PanPivot!X:X) -> 0 | BQ11: =_xlfn.XLOOKUP(A11,VacPivot!A:A,VacPivot!AC:AC) -> 0 | BR11: {=SUM(IFERROR(BP11:BQ11,0))} -> 0 | BS11: =_xlfn.XLOOKUP(Summing.bothpivots!A11,PanPivot!A:A,PanPivot!Y:Y) -> 0 | BT11: =_xlfn.XLOOKUP(A11,VacPivot!A:A,VacPivot!AD:AD) -> 0 | BU11: {=SUM(IFERROR(BS11:BT11,0))} -> 0 | BV11: =_xlfn.XLOOKUP(A11,PanPivot!A:A,PanPivot!Z:Z) -> 0 | BW11: =_xlfn.XLOOKUP(A11,VacPivot!A:A,VacPivot!AE:AE) -> 0 | BX11: {=SUM(IFERROR(BV11:BW11,0))} -> 0 | BY11: =_xlfn.XLOOKUP(A11,PanPivot!A:A,PanPivot!AA:AA) -> 0 | BZ11: =_xlfn.XLOOKUP(A11,VacPivot!A:A,VacPivot!AG:AG) -> 0 | CA11: {=SUM(IFERROR(BY11:BZ11,0))} -> 0 | CB11: =_xlfn.XLOOKUP(A11,PanPivot!A:A,PanPivot!AB:AB) -> 0 | CC11: =_xlfn.XLOOKUP(A11,VacPivot!A:A,VacPivot!AH:AH) -> 0 | CD11: {=SUM(IFERROR(CB11:CC11,0))} -> 0 | CE11: =_xlfn.XLOOKUP(A11,PanPivot!A:A,PanPivot!AC:AC) -> 0 | CF11: =_xlfn.XLOOKUP(A11,VacPivot!A:A,VacPivot!AI:AI) -> 0 | CG11: {=SUM(IFERROR(CE11:CF11,0))} -> 0 | CH11: =_xlfn.XLOOKUP(A11,PanPivot!A:A,PanPivot!AD:AD) -> 0 | CI11: =_xlfn.XLOOKUP(A11,VacPivot!A:A,VacPivot!AJ:AJ) -> 0 | CJ11: {=SUM(IFERROR(CH11:CI11,0))} -> 0 | CK11: =_xlfn.XLOOKUP(A11,PanPivot!A:A,PanPivot!AE:AE) -> 0 | CL11: =_xlfn.XLOOKUP(A11,VacPivot!A:A,VacPivot!AL:AL) -> 0 | CM11: {=SUM(IFERROR(CK11:CL11,0))} -> 0 | CN11: =_xlfn.XLOOKUP(A11,PanPivot!A:A,PanPivot!AF:AF) -> 0 | CO11: =_xlfn.XLOOKUP(A11,VacPivot!A:A,VacPivot!AM:AM) -> 0 | CP11: {=SUM(IFERROR(CN11:CO11,0))} -> 0 | CQ11: =_xlfn.XLOOKUP(A11,PanPivot!A:A,PanPivot!AG:AG) -> 0 | CR11: =_xlfn.XLOOKUP(A11,VacPivot!A:A,VacPivot!AN:AN) -> 0 | CS11: {=SUM(IFERROR(CQ11:CR11,0))} -> 0
A12: Andrena.wilkella | B12: =_xlfn.XLOOKUP(A12,PanPivot!A:A,PanPivot!B:B) -> 0 | C12: =_xlfn.XLOOKUP(A12,VacPivot!A:A,VacPivot!B:B) -> 2 | D12: {=SUM(IFERROR(B12:C12,0))} -> 2 | E12: =_xlfn.XLOOKUP(A12,PanPivot!A:A,PanPivot!C:C) -> 0 | F12: =_xlfn.XLOOKUP(A12,VacPivot!A:A,VacPivot!D:D) -> 0 | G12: {=SUM(IFERROR(E12:F12,0))} -> 0 | H12: =_xlfn.XLOOKUP(A12,PanPivot!A:A,PanPivot!D:D) -> 1 | I12: =_xlfn.XLOOKUP(A12,VacPivot!A:A,VacPivot!E:E) -> 3 | J12: {=SUM(IFERROR(H12:I12,0))} -> 4 | K12: =_xlfn.XLOOKUP(A12,PanPivot!A:A,PanPivot!E:E) -> 0 | L12: =_xlfn.XLOOKUP(Summing.bothpivots!A12,VacPivot!A:A,VacPivot!F:F) -> 0 | M12: {=SUM(IFERROR(K12:L12,0))} -> 0 | N12: =_xlfn.XLOOKUP(A12,PanPivot!A:A,PanPivot!F:F) -> 2 | O12: =_xlfn.XLOOKUP(A12,VacPivot!A:A,VacPivot!AO:AO) -> 0 | P12: {=SUM(IFERROR(N12:O12,0))} -> 2 | Q12: =_xlfn.XLOOKUP(A12,PanPivot!A:A,PanPivot!G:G) -> 10 | R12: =_xlfn.XLOOKUP(A12,VacPivot!A:A,VacPivot!H:H) -> 2 | S12: {=SUM(IFERROR(Q12:R12,0))} -> 12 | T12: =_xlfn.XLOOKUP(A12,PanPivot!A:A,PanPivot!H:H) -> 4 | U12: =_xlfn.XLOOKUP(A12,VacPivot!A:A,VacPivot!I:I) -> 0 | V12: {=SUM(IFERROR(T12:U12,0))} -> 4 | W12: =_xlfn.XLOOKUP(A12,PanPivot!A:A,PanPivot!I:I) -> 0 | X12: =_xlfn.XLOOKUP(A12,VacPivot!A:A,VacPivot!J:J) -> 2 | Y12: {=SUM(IFERROR(W12:X12,0))} -> 2 | Z12: =_xlfn.XLOOKUP(A12,PanPivot!A:A,PanPivot!J:J) -> 1 | AA12: =_xlfn.XLOOKUP(A12,VacPivot!A:A,VacPivot!K:K) -> 0 | AB12: {=SUM(IFERROR(Z12:AA12,0))} -> 1 | AC12: =_xlfn.XLOOKUP(A12,PanPivot!A:A,PanPivot!K:K) -> 1 | AD12: =_xlfn.XLOOKUP(A12,VacPivot!A:A,VacPivot!M:M) -> 0 | AE12: {=SUM(IFERROR(AC12:AD12,0))} -> 1 | AF12: =_xlfn.XLOOKUP(A12,PanPivot!A:A,PanPivot!L:L) -> 1 | AG12: =_xlfn.XLOOKUP(A12,VacPivot!A:A,VacPivot!N:N) -> 0 | AH12: {=SUM(IFERROR(AF12:AG12,0))} -> 1 | AI12: =_xlfn.XLOOKUP(A12,PanPivot!A:A,PanPivot!M:M) -> 0 | AJ12: =_xlfn.XLOOKUP(A12,VacPivot!A:A,VacPivot!O:O) -> 1 | AK12: {=SUM(IFERROR(AI12:AJ12,0))} -> 1 | AL12: =_xlfn.XLOOKUP(A12,PanPivot!A:A,PanPivot!N:N) -> 0 | AM12: =_xlfn.XLOOKUP(A12,VacPivot!A:A,VacPivot!P:P) -> 0 | AN12: {=SUM(IFERROR(AL12:AM12,0))} -> 0 | AO12: =_xlfn.XLOOKUP(A12,PanPivot!A:A,PanPivot!O:O) -> 0 | AP12: =_xlfn.XLOOKUP(A12,VacPivot!A:A,VacPivot!R:R) -> 0 | AQ12: {=SUM(IFERROR(AO12:AP12,0))} -> 0 | AR12: =_xlfn.XLOOKUP(A12,PanPivot!A:A,PanPivot!P:P) -> 0 | AS12: =_xlfn.XLOOKUP(A12,VacPivot!A:A,VacPivot!S:S) -> 3 | AT12: {=SUM(IFERROR(AR12:AS12,0))} -> 3 | AU12: =_xlfn.XLOOKUP(A12,PanPivot!A:A,PanPivot!Q:Q) -> 0 | AV12: =_xlfn.XLOOKUP(A12,VacPivot!A:A,VacPivot!T:T) -> 2 | AW12: {=SUM(IFERROR(AU12:AV12,0))} -> 2 | AX12: =_xlfn.XLOOKUP(A12,PanPivot!A:A,PanPivot!R:R) -> 0 | AY12: =_xlfn.XLOOKUP(A12,VacPivot!A:A,VacPivot!U:U) -> 0 | AZ12: {=SUM(IFERROR(AX12:AY12,0))} -> 0 | BA12: =_xlfn.XLOOKUP(A12,PanPivot!A:A,PanPivot!S:S) -> 0 | BB12: =_xlfn.XLOOKUP(A12,VacPivot!A:A,VacPivot!W:W) -> 2 | BC12: {=SUM(IFERROR(BA12:BB12,0))} -> 2 | BD12: =_xlfn.XLOOKUP(A12,PanPivot!A:A,PanPivot!T:T) -> 4 | BE12: =_xlfn.XLOOKUP(A12,VacPivot!A:A,VacPivot!X:X) -> 1 | BF12: {=SUM(IFERROR(BD12:BE12,0))} -> 5 | BG12: =_xlfn.XLOOKUP(A12,PanPivot!A:A,PanPivot!U:U) -> 7 | BH12: =_xlfn.XLOOKUP(Summing.bothpivots!A12,VacPivot!A:A,VacPivot!Y:Y) -> 1 | BI12: {=SUM(IFERROR(BG12:BH12,0))} -> 8 | BJ12: =_xlfn.XLOOKUP(A12,PanPivot!A:A,PanPivot!V:V) -> 0 | BK12: =_xlfn.XLOOKUP(A12,VacPivot!A:A,VacPivot!Z:Z) -> 3 | BL12: {=SUM(IFERROR(BJ12:BK12,0))} -> 3 | BM12: =_xlfn.XLOOKUP(A12,PanPivot!A:A,PanPivot!W:W) -> 1 | BN12: =_xlfn.XLOOKUP(A12,VacPivot!A:A,VacPivot!AB:AB) -> 1 | BO12: {=SUM(IFERROR(BM12:BN12,0))} -> 2 | BP12: =_xlfn.XLOOKUP(A12,PanPivot!A:A,PanPivot!X:X) -> 0 | BQ12: =_xlfn.XLOOKUP(A12,VacPivot!A:A,VacPivot!AC:AC) -> 0 | BR12: {=SUM(IFERROR(BP12:BQ12,0))} -> 0 | BS12: =_xlfn.XLOOKUP(Summing.bothpivots!A12,PanPivot!A:A,PanPivot!Y:Y) -> 0 | BT12: =_xlfn.XLOOKUP(A12,VacPivot!A:A,VacPivot!AD:AD) -> 2 | BU12: {=SUM(IFERROR(BS12:BT12,0))} -> 2 | BV12: =_xlfn.XLOOKUP(A12,PanPivot!A:A,PanPivot!Z:Z) -> 0 | BW12: =_xlfn.XLOOKUP(A12,VacPivot!A:A,VacPivot!AE:AE) -> 0 | BX12: {=SUM(IFERROR(BV12:BW12,0))} -> 0 | BY12: =_xlfn.XLOOKUP(A12,PanPivot!A:A,PanPivot!AA:AA) -> 0 | BZ12: =_xlfn.XLOOKUP(A12,VacPivot!A:A,VacPivot!AG:AG) -> 1 | CA12: {=SUM(IFERROR(BY12:BZ12,0))} -> 1 | CB12: =_xlfn.XLOOKUP(A12,PanPivot!A:A,PanPivot!AB:AB) -> 0 | CC12: =_xlfn.XLOOKUP(A12,VacPivot!A:A,VacPivot!AH:AH) -> 1 | CD12: {=SUM(IFERROR(CB12:CC12,0))} -> 1 | CE12: =_xlfn.XLOOKUP(A12,PanPivot!A:A,PanPivot!AC:AC) -> 0 | CF12: =_xlfn.XLOOKUP(A12,VacPivot!A:A,VacPivot!AI:AI) -> 2 | CG12: {=SUM(IFERROR(CE12:CF12,0))} -> 2 | CH12: =_xlfn.XLOOKUP(A12,PanPivot!A:A,PanPivot!AD:AD) -> 0 | CI12: =_xlfn.XLOOKUP(A12,VacPivot!A:A,VacPivot!AJ:AJ) -> 2 | CJ12: {=SUM(IFERROR(CH12:CI12,0))} -> 2 | CK12: =_xlfn.XLOOKUP(A12,PanPivot!A:A,PanPivot!AE:AE) -> 0 | CL12: =_xlfn.XLOOKUP(A12,VacPivot!A:A,VacPivot!AL:AL) -> 4 | CM12: {=SUM(IFERROR(CK12:CL12,0))} -> 4 | CN12: =_xlfn.XLOOKUP(A12,PanPivot!A:A,PanPivot!AF:AF) -> 1 | CO12: =_xlfn.XLOOKUP(A12,VacPivot!A:A,VacPivot!AM:AM) -> 3 | CP12: {=SUM(IFERROR(CN12:CO12,0))} -> 4 | CQ12: =_xlfn.XLOOKUP(A12,PanPivot!A:A,PanPivot!AG:AG) -> 0 | CR12: =_xlfn.XLOOKUP(A12,VacPivot!A:A,VacPivot!AN:AN) -> 5 | CS12: {=SUM(IFERROR(CQ12:CR12,0))} -> 5
A13: Anthidium.manicatum | B13: =_xlfn.XLOOKUP(A13,PanPivot!A:A,PanPivot!B:B) -> 0 | C13: =_xlfn.XLOOKUP(A13,VacPivot!A:A,VacPivot!B:B) -> 0 | D13: {=SUM(IFERROR(B13:C13,0))} -> 0 | E13: =_xlfn.XLOOKUP(A13,PanPivot!A:A,PanPivot!C:C) -> 0 | F13: =_xlfn.XLOOKUP(A13,VacPivot!A:A,VacPivot!D:D) -> 0 | G13: {=SUM(IFERROR(E13:F13,0))} -> 0 | H13: =_xlfn.XLOOKUP(A13,PanPivot!A:A,PanPivot!D:D) -> 0 | I13: =_xlfn.XLOOKUP(A13,VacPivot!A:A,VacPivot!E:E) -> 0 | J13: {=SUM(IFERROR(H13:I13,0))} -> 0 | K13: =_xlfn.XLOOKUP(A13,PanPivot!A:A,PanPivot!E:E) -> 0 | L13: =_xlfn.XLOOKUP(Summing.bothpivots!A13,VacPivot!A:A,VacPivot!F:F) -> 0 | M13: {=SUM(IFERROR(K13:L13,0))} -> 0 | N13: =_xlfn.XLOOKUP(A13,PanPivot!A:A,PanPivot!F:F) -> 0 | O13: =_xlfn.XLOOKUP(A13,VacPivot!A:A,VacPivot!AO:AO) -> 0 | P13: {=SUM(IFERROR(N13:O13,0))} -> 0 | Q13: =_xlfn.XLOOKUP(A13,PanPivot!A:A,PanPivot!G:G) -> 1 | R13: =_xlfn.XLOOKUP(A13,VacPivot!A:A,VacPivot!H:H) -> 0 | S13: {=SUM(IFERROR(Q13:R13,0))} -> 1 | T13: =_xlfn.XLOOKUP(A13,PanPivot!A:A,PanPivot!H:H) -> 1 | U13: =_xlfn.XLOOKUP(A13,VacPivot!A:A,VacPivot!I:I) -> 2 | V13: {=SUM(IFERROR(T13:U13,0))} -> 3 | W13: =_xlfn.XLOOKUP(A13,PanPivot!A:A,PanPivot!I:I) -> 0 | X13: =_xlfn.XLOOKUP(A13,VacPivot!A:A,VacPivot!J:J) -> 1 | Y13: {=SUM(IFERROR(W13:X13,0))} -> 1 | Z13: =_xlfn.XLOOKUP(A13,PanPivot!A:A,PanPivot!J:J) -> 0 | AA13: =_xlfn.XLOOKUP(A13,VacPivot!A:A,VacPivot!K:K) -> 0 | AB13: {=SUM(IFERROR(Z13:AA13,0))} -> 0 | AC13: =_xlfn.XLOOKUP(A13,PanPivot!A:A,PanPivot!K:K) -> 0 | AD13: =_xlfn.XLOOKUP(A13,VacPivot!A:A,VacPivot!M:M) -> 1 | AE13: {=SUM(IFERROR(AC13:AD13,0))} -> 1 | AF13: =_xlfn.XLOOKUP(A13,PanPivot!A:A,PanPivot!L:L) -> 0 | AG13: =_xlfn.XLOOKUP(A13,VacPivot!A:A,VacPivot!N:N) -> 0 | AH13: {=SUM(IFERROR(AF13:AG13,0))} -> 0 | AI13: =_xlfn.XLOOKUP(A13,PanPivot!A:A,PanPivot!M:M) -> 0 | AJ13: =_xlfn.XLOOKUP(A13,VacPivot!A:A,VacPivot!O:O) -> 0 | AK13: {=SUM(IFERROR(AI13:AJ13,0))} -> 0 | AL13: =_xlfn.XLOOKUP(A13,PanPivot!A:A,PanPivot!N:N) -> 0 | AM13: =_xlfn.XLOOKUP(A13,VacPivot!A:A,VacPivot!P:P) -> 0 | AN13: {=SUM(IFERROR(AL13:AM13,0))} -> 0 | AO13: =_xlfn.XLOOKUP(A13,PanPivot!A:A,PanPivot!O:O) -> 0 | AP13: =_xlfn.XLOOKUP(A13,VacPivot!A:A,VacPivot!R:R) -> 0 | AQ13: {=SUM(IFERROR(AO13:AP13,0))} -> 0 | AR13: =_xlfn.XLOOKUP(A13,PanPivot!A:A,PanPivot!P:P) -> 0 | AS13: =_xlfn.XLOOKUP(A13,VacPivot!A:A,VacPivot!S:S) -> 1 | AT13: {=SUM(IFERROR(AR13:AS13,0))} -> 1 | AU13: =_xlfn.XLOOKUP(A13,PanPivot!A:A,PanPivot!Q:Q) -> 0 | AV13: =_xlfn.XLOOKUP(A13,VacPivot!A:A,VacPivot!T:T) -> 0 | AW13: {=SUM(IFERROR(AU13:AV13,0))} -> 0 | AX13: =_xlfn.XLOOKUP(A13,PanPivot!A:A,PanPivot!R:R) -> 0 | AY13: =_xlfn.XLOOKUP(A13,VacPivot!A:A,VacPivot!U:U) -> 0 | AZ13: {=SUM(IFERROR(AX13:AY13,0))} -> 0 | BA13: =_xlfn.XLOOKUP(A13,PanPivot!A:A,PanPivot!S:S) -> 1 | BB13: =_xlfn.XLOOKUP(A13,VacPivot!A:A,VacPivot!W:W) -> 0 | BC13: {=SUM(IFERROR(BA13:BB13,0))} -> 1 | BD13: =_xlfn.XLOOKUP(A13,PanPivot!A:A,PanPivot!T:T) -> 0 | BE13: =_xlfn.XLOOKUP(A13,VacPivot!A:A,VacPivot!X:X) -> 0 | BF13: {=SUM(IFERROR(BD13:BE13,0))} -> 0 | BG13: =_xlfn.XLOOKUP(A13,PanPivot!A:A,PanPivot!U:U) -> 0 | BH13: =_xlfn.XLOOKUP(Summing.bothpivots!A13,VacPivot!A:A,VacPivot!Y:Y) -> 0 | BI13: {=SUM(IFERROR(BG13:BH13,0))} -> 0 | BJ13: =_xlfn.XLOOKUP(A13,PanPivot!A:A,PanPivot!V:V) -> 0 | BK13: =_xlfn.XLOOKUP(A13,VacPivot!A:A,VacPivot!Z:Z) -> 0 | BL13: {=SUM(IFERROR(BJ13:BK13,0))} -> 0 | BM13: =_xlfn.XLOOKUP(A13,PanPivot!A:A,PanPivot!W:W) -> 0 | BN13: =_xlfn.XLOOKUP(A13,VacPivot!A:A,VacPivot!AB:AB) -> 0 | BO13: {=SUM(IFERROR(BM13:BN13,0))} -> 0 | BP13: =_xlfn.XLOOKUP(A13,PanPivot!A:A,PanPivot!X:X) -> 0 | BQ13: =_xlfn.XLOOKUP(A13,VacPivot!A:A,VacPivot!AC:AC) -> 0 | BR13: {=SUM(IFERROR(BP13:BQ13,0))} -> 0 | BS13: =_xlfn.XLOOKUP(Summing.bothpivots!A13,PanPivot!A:A,PanPivot!Y:Y) -> 0 | BT13: =_xlfn.XLOOKUP(A13,VacPivot!A:A,VacPivot!AD:AD) -> 0 | BU13: {=SUM(IFERROR(BS13:BT13,0))} -> 0 | BV13: =_xlfn.XLOOKUP(A13,PanPivot!A:A,PanPivot!Z:Z) -> 0 | BW13: =_xlfn.XLOOKUP(A13,VacPivot!A:A,VacPivot!AE:AE) -> 0 | BX13: {=SUM(IFERROR(BV13:BW13,0))} -> 0 | BY13: =_xlfn.XLOOKUP(A13,PanPivot!A:A,PanPivot!AA:AA) -> 1 | BZ13: =_xlfn.XLOOKUP(A13,VacPivot!A:A,VacPivot!AG:AG) -> 0 | CA13: {=SUM(IFERROR(BY13:BZ13,0))} -> 1 | CB13: =_xlfn.XLOOKUP(A13,PanPivot!A:A,PanPivot!AB:AB) -> 0 | CC13: =_xlfn.XLOOKUP(A13,VacPivot!A:A,VacPivot!AH:AH) -> 0 | CD13: {=SUM(IFERROR(CB13:CC13,0))} -> 0 | CE13: =_xlfn.XLOOKUP(A13,PanPivot!A:A,PanPivot!AC:AC) -> 0 | CF13: =_xlfn.XLOOKUP(A13,VacPivot!A:A,VacPivot!AI:AI) -> 0 | CG13: {=SUM(IFERROR(CE13:CF13,0))} -> 0 | CH13: =_xlfn.XLOOKUP(A13,PanPivot!A:A,PanPivot!AD:AD) -> 0 | CI13: =_xlfn.XLOOKUP(A13,VacPivot!A:A,VacPivot!AJ:AJ) -> 0 | CJ13: {=SUM(IFERROR(CH13:CI13,0))} -> 0 | CK13: =_xlfn.XLOOKUP(A13,PanPivot!A:A,PanPivot!AE:AE) -> 0 | CL13: =_xlfn.XLOOKUP(A13,VacPivot!A:A,VacPivot!AL:AL) -> 0 | CM13: {=SUM(IFERROR(CK13:CL13,0))} -> 0 | CN13: =_xlfn.XLOOKUP(A13,PanPivot!A:A,PanPivot!AF:AF) -> 5 | CO13: =_xlfn.XLOOKUP(A13,VacPivot!A:A,VacPivot!AM:AM) -> 0 | CP13: {=SUM(IFERROR(CN13:CO13,0))} -> 5 | CQ13: =_xlfn.XLOOKUP(A13,PanPivot!A:A,PanPivot!AG:AG) -> 1 | CR13: =_xlfn.XLOOKUP(A13,VacPivot!A:A,VacPivot!AN:AN) -> 0 | CS13: {=SUM(IFERROR(CQ13:CR13,0))} -> 1
